Workbook
Name ActualNumberOfPayments: IFERROR(IF(LoanIsGood,IF(PaymentsPerYear=1,1,MATCH(0.01,End_Bal,-1)+1)),"")
Name ActualNumberOfPayments: IFERROR(IF(LoanIsGood,IF(PaymentsPerYear=1,1,MATCH(0.01,End_Bal,-1)+1)),"")
Name error.tol: #REF!
Name fore.start: #REF!
Name IQ_CH: 110000
Name IQ_CQ: 5000
Name IQ_CY: 10000
Name IQ_DAILY: 500000
Name IQ_FH: 100000
Name IQ_FQ: 500
Name IQ_FY: 1000
Name IQ_LTM: 2000
Name IQ_MONTH: 15000
Name IQ_NTM: 6000
Name IQ_WEEK: 50000
Name IQ_YTD: 3000
Name Mapping_AdvisoryIncome: #REF!
Name Mapping_AmortisationDepr: #REF!
Name Mapping_CostofFinace: #REF!
Name Mapping_CurrentAssets: #REF!
Name Mapping_CurrentLiabilities: #REF!
Name Mapping_DirectCosts: #REF!
Name Mapping_Equity: #REF!
Name Mapping_NonCurrentAssets: #REF!
Name Mapping_NonCurrentLiabilities: #REF!
Name Mapping_OPEX: #REF!
Name month.1: #REF!
Name Slicer_Quarter: #N/A
Name trans.date: #REF!
Name US_case: #REF!

Sheet Project Budget
B2: JMAN Engagement Budget Calculator | L2: Version Mar 2025
B4: Note this tool is intended for internal use only for quoting purposes and should not be forwarded to any external parties.
B6: 0. Instructions:
B8: 1. Please make a copy of this template into the Project Budget folder for your specific opportunity before making changes. Do NOT change anything in this template file itself.
B9: 2. Only fields in blue text / background are editable. Do NOT edit any other cells.
B10: 3. Add more rows for additional resources and planned cost as needed.
B11: 4. Once completed, please submit the Engagement Budget to scoping@jmangroup.com for approval. This step is mandatory before confirming work with a client.
B12: 5. For questions please contact amandavanheerden@jmangroup.com.
B14: 1. Engagement information
B16: Client code | D16: Please enter 3 digit JMAN client code
B17: Project name | D17: Please enter per Hubspot deal
B18: Engagement style | C18: Project | D18: Please select from drop-down list
B19: Project Type (Proposition CoE) | C19: Core Reporting | D19: Please select from drop-down list
B20: Applied project type multiplier | C20: =INDEX('Rate Card & Lookups'!$P$10:$P$21,MATCH('Project Budget'!$C$19,'Rate Card & Lookups'!$O$10:$O$21,0)) -> 1
B21: Client Geography | C21: USA | D21: Please select from drop-down list
B22: Payment terms | C22: JMAN standard (EOM + 20 days) | D22: Please select from drop-down list. Note: payment terms >EOM+30 days require Finance approval and will incur a premium.
B23: Effective payment term premium | C23: =IF(C22="","",VLOOKUP(C22,'Rate Card & Lookups'!$AI$10:$AJ$13,2,FALSE)) -> 0 | D23: Applied to overall budget amount
B25: 2. Resources and professional fees
B27: Notes for Projects: - Charge for AP/P time (min. 12.5%) | C27: Location of team member affects the cost rates. | D27: Charge SC/C as Engagement Manager if there is no Manager | E27: Specify project start and end date for calculation of # working days in column H). If start date is unknown, enter # working days in column H. | G27: Specify utilisation (min. 1 hr/day) | J27: Specify # working days (if project start date is unknown)
B28: - Chennai team members in consultant roles to be charged as AC | N28: Cost rate: Available days
B29: Role | C29: Location | D29: Charge as Engagement Manager? | E29: Start Date | F29: End Date | G29: Hours per Day | H29: Base Day Rate | I29: Cost Day Rate | J29: Working Days | K29: Allocation | L29: Effective Day Rate | M29: Total fees | N29: Cost | O29: Margin | P29: Margin %
E30: YYYY-MM-DD | F30: YYYY-MM-DD | H30: =K50 -> USD | I30: =K50 -> USD | J30: # | K30: % | L30: =K50 -> USD | M30: =K50 -> USD | N30: =K50 -> USD | O30: =K50 -> USD
B31: Consultant | C31: IN | G31: 8 | H31: =IF(D31="Yes",HLOOKUP($K$50,'Rate Card & Lookups'!$D$9:$F$39,4,FALSE)*$C$20,_xlfn.IFNA(INDEX('Rate Card & Lookups'!$D$10:$F$39,MATCH($B31&C31,'Rate Card & Lookups'!$A$10:$A$39,0),MATCH($H$30,'Rate Card & Lookups'!$D$9:$F$9,0))*$C$20,"")) -> 682.5 | I31: =_xlfn.IFNA(INDEX('Rate Card & Lookups'!$G$10:$I$39,MATCH($B31&C31,'Rate Card & Lookups'!$A$10:$A$39,0),MATCH($I$30,'Rate Card & Lookups'!$G$9:$I$9,0)),"") -> 91 | J31: 5 | K31: =IF(ISBLANK(G31),"",G31/8) -> 1 | L31: =IFERROR(H31*K31,"") -> 682.5 | M31: =IFERROR(L31*J31,"") -> 3412.5 | N31: =IFERROR(I31*K31*J31,"") -> 455 | O31: =IFERROR(M31-N31,"") -> 2957.5 | P31: =IFERROR(O31/M31,"") -> 0.86666667
B32: Senior Associate Consultant | C32: IN | G32: 8 | H32: =IF(D32="Yes",HLOOKUP($K$50,'Rate Card & Lookups'!$D$9:$F$39,4,FALSE)*$C$20,_xlfn.IFNA(INDEX('Rate Card & Lookups'!$D$10:$F$39,MATCH($B32&C32,'Rate Card & Lookups'!$A$10:$A$39,0),MATCH($H$30,'Rate Card & Lookups'!$D$9:$F$9,0))*$C$20,"")) -> 682.5 | I32: =_xlfn.IFNA(INDEX('Rate Card & Lookups'!$G$10:$I$39,MATCH($B32&C32,'Rate Card & Lookups'!$A$10:$A$39,0),MATCH($I$30,'Rate Card & Lookups'!$G$9:$I$9,0)),"") -> 71.5 | J32: 5 | K32: =IF(ISBLANK(G32),"",G32/8) -> 1 | L32: =IFERROR(H32*K32,"") -> 682.5 | M32: =IFERROR(L32*J32,"") -> 3412.5 | N32: =IFERROR(I32*K32*J32,"") -> 357.5 | O32: =IFERROR(M32-N32,"") -> 3055 | P32: =IFERROR(O32/M32,"") -> 0.8952381
B33: Associate Consultant | C33: IN | G33: 8 | H33: =IF(D33="Yes",HLOOKUP($K$50,'Rate Card & Lookups'!$D$9:$F$39,4,FALSE)*$C$20,_xlfn.IFNA(INDEX('Rate Card & Lookups'!$D$10:$F$39,MATCH($B33&C33,'Rate Card & Lookups'!$A$10:$A$39,0),MATCH($H$30,'Rate Card & Lookups'!$D$9:$F$9,0))*$C$20,"")) -> 585 | I33: =_xlfn.IFNA(INDEX('Rate Card & Lookups'!$G$10:$I$39,MATCH($B33&C33,'Rate Card & Lookups'!$A$10:$A$39,0),MATCH($I$30,'Rate Card & Lookups'!$G$9:$I$9,0)),"") -> 58.5 | J33: 5 | K33: =IF(ISBLANK(G33),"",G33/8) -> 1 | L33: =IFERROR(H33*K33,"") -> 585 | M33: =IFERROR(L33*J33,"") -> 2925 | N33: =IFERROR(I33*K33*J33,"") -> 292.5 | O33: =IFERROR(M33-N33,"") -> 2632.5 | P33: =IFERROR(O33/M33,"") -> 0.9
B34: Principal Technology Architect | C34: IN | G34: 8 | H34: =IF(D34="Yes",HLOOKUP($K$50,'Rate Card & Lookups'!$D$9:$F$39,4,FALSE)*$C$20,_xlfn.IFNA(INDEX('Rate Card & Lookups'!$D$10:$F$39,MATCH($B34&C34,'Rate Card & Lookups'!$A$10:$A$39,0),MATCH($H$30,'Rate Card & Lookups'!$D$9:$F$9,0))*$C$20,"")) -> 845 | I34: =_xlfn.IFNA(INDEX('Rate Card & Lookups'!$G$10:$I$39,MATCH($B34&C34,'Rate Card & Lookups'!$A$10:$A$39,0),MATCH($I$30,'Rate Card & Lookups'!$G$9:$I$9,0)),"") -> 299 | J34: 5 | K34: =IF(ISBLANK(G34),"",G34/8) -> 1 | L34: =IFERROR(H34*K34,"") -> 845 | M34: =IFERROR(L34*J34,"") -> 4225 | N34: =IFERROR(I34*K34*J34,"") -> 1495 | O34: =IFERROR(M34-N34,"") -> 2730 | P34: =IFERROR(O34/M34,"") -> 0.64615385
B35: Technical Solutions Architect | C35: IN | G35: 8 | H35: =IF(D35="Yes",HLOOKUP($K$50,'Rate Card & Lookups'!$D$9:$F$39,4,FALSE)*$C$20,_xlfn.IFNA(INDEX('Rate Card & Lookups'!$D$10:$F$39,MATCH($B35&C35,'Rate Card & Lookups'!$A$10:$A$39,0),MATCH($H$30,'Rate Card & Lookups'!$D$9:$F$9,0))*$C$20,"")) -> 747.5 | I35: =_xlfn.IFNA(INDEX('Rate Card & Lookups'!$G$10:$I$39,MATCH($B35&C35,'Rate Card & Lookups'!$A$10:$A$39,0),MATCH($I$30,'Rate Card & Lookups'!$G$9:$I$9,0)),"") -> 182 | J35: 5 | K35: =IF(ISBLANK(G35),"",G35/8) -> 1 | L35: =IFERROR(H35*K35,"") -> 747.5 | M35: =IFERROR(L35*J35,"") -> 3737.5 | N35: =IFERROR(I35*K35*J35,"") -> 910 | O35: =IFERROR(M35-N35,"") -> 2827.5 | P35: =IFERROR(O35/M35,"") -> 0.75652174
B36: Intern Technology | C36: IN | G36: 8 | H36: =IF(D36="Yes",HLOOKUP($K$50,'Rate Card & Lookups'!$D$9:$F$39,4,FALSE)*$C$20,_xlfn.IFNA(INDEX('Rate Card & Lookups'!$D$10:$F$39,MATCH($B36&C36,'Rate Card & Lookups'!$A$10:$A$39,0),MATCH($H$30,'Rate Card & Lookups'!$D$9:$F$9,0))*$C$20,"")) -> 390 | I36: =_xlfn.IFNA(INDEX('Rate Card & Lookups'!$G$10:$I$39,MATCH($B36&C36,'Rate Card & Lookups'!$A$10:$A$39,0),MATCH($I$30,'Rate Card & Lookups'!$G$9:$I$9,0)),"") -> 26 | J36: 5 | K36: =IF(ISBLANK(G36),"",G36/8) -> 1 | L36: =IFERROR(H36*K36,"") -> 390 | M36: =IFERROR(L36*J36,"") -> 1950 | N36: =IFERROR(I36*K36*J36,"") -> 130 | O36: =IFERROR(M36-N36,"") -> 1820 | P36: =IFERROR(O36/M36,"") -> 0.93333333
B37: Senior Solutions Consultant | C37: UK | G37: 8 | H37: =IF(D37="Yes",HLOOKUP($K$50,'Rate Card & Lookups'!$D$9:$F$39,4,FALSE)*$C$20,_xlfn.IFNA(INDEX('Rate Card & Lookups'!$D$10:$F$39,MATCH($B37&C37,'Rate Card & Lookups'!$A$10:$A$39,0),MATCH($H$30,'Rate Card & Lookups'!$D$9:$F$9,0))*$C$20,"")) -> 2798.25 | I37: =_xlfn.IFNA(INDEX('Rate Card & Lookups'!$G$10:$I$39,MATCH($B37&C37,'Rate Card & Lookups'!$A$10:$A$39,0),MATCH($I$30,'Rate Card & Lookups'!$G$9:$I$9,0)),"") -> 630.5 | J37: 5 | K37: =IF(ISBLANK(G37),"",G37/8) -> 1 | L37: =IFERROR(H37*K37,"") -> 2798.25 | M37: =IFERROR(L37*J37,"") -> 13991.25 | N37: =IFERROR(I37*K37*J37,"") -> 3152.5 | O37: =IFERROR(M37-N37,"") -> 10838.75 | P37: =IFERROR(O37/M37,"") -> 0.7746806
B38: Solutions Consultant | C38: UK | G38: 8 | H38: =IF(D38="Yes",HLOOKUP($K$50,'Rate Card & Lookups'!$D$9:$F$39,4,FALSE)*$C$20,_xlfn.IFNA(INDEX('Rate Card & Lookups'!$D$10:$F$39,MATCH($B38&C38,'Rate Card & Lookups'!$A$10:$A$39,0),MATCH($H$30,'Rate Card & Lookups'!$D$9:$F$9,0))*$C$20,"")) -> 2457 | I38: =_xlfn.IFNA(INDEX('Rate Card & Lookups'!$G$10:$I$39,MATCH($B38&C38,'Rate Card & Lookups'!$A$10:$A$39,0),MATCH($I$30,'Rate Card & Lookups'!$G$9:$I$9,0)),"") -> 572 | J38: 5 | K38: =IF(ISBLANK(G38),"",G38/8) -> 1 | L38: =IFERROR(H38*K38,"") -> 2457 | M38: =IFERROR(L38*J38,"") -> 12285 | N38: =IFERROR(I38*K38*J38,"") -> 2860 | O38: =IFERROR(M38-N38,"") -> 9425 | P38: =IFERROR(O38/M38,"") -> 0.76719577
B39: Technical Solutions Architect | C39: USA | G39: 8 | H39: =IF(D39="Yes",HLOOKUP($K$50,'Rate Card & Lookups'!$D$9:$F$39,4,FALSE)*$C$20,_xlfn.IFNA(INDEX('Rate Card & Lookups'!$D$10:$F$39,MATCH($B39&C39,'Rate Card & Lookups'!$A$10:$A$39,0),MATCH($H$30,'Rate Card & Lookups'!$D$9:$F$9,0))*$C$20,"")) -> 3233.75 | I39: =_xlfn.IFNA(INDEX('Rate Card & Lookups'!$G$10:$I$39,MATCH($B39&C39,'Rate Card & Lookups'!$A$10:$A$39,0),MATCH($I$30,'Rate Card & Lookups'!$G$9:$I$9,0)),"") -> 1241.5 | J39: 5 | K39: =IF(ISBLANK(G39),"",G39/8) -> 1 | L39: =IFERROR(H39*K39,"") -> 3233.75 | M39: =IFERROR(L39*J39,"") -> 16168.75 | N39: =IFERROR(I39*K39*J39,"") -> 6207.5 | O39: =IFERROR(M39-N39,"") -> 9961.25 | P39: =IFERROR(O39/M39,"") -> 0.6160804
H40: =IF(D40="Yes",HLOOKUP($K$50,'Rate Card & Lookups'!$D$9:$F$39,4,FALSE)*$C$20,_xlfn.IFNA(INDEX('Rate Card & Lookups'!$D$10:$F$39,MATCH($B40&C40,'Rate Card & Lookups'!$A$10:$A$39,0),MATCH($H$30,'Rate Card & Lookups'!$D$9:$F$9,0))*$C$20,"")) | I40: =_xlfn.IFNA(INDEX('Rate Card & Lookups'!$G$10:$I$39,MATCH($B40&C40,'Rate Card & Lookups'!$A$10:$A$39,0),MATCH($I$30,'Rate Card & Lookups'!$G$9:$I$9,0)),"") | K40: =IF(ISBLANK(G40),"",G40/8) | L40: =IFERROR(H40*K40,"") | M40: =IFERROR(L40*J40,"") | N40: =IFERROR(I40*K40*J40,"") | O40: =IFERROR(M40-N40,"") | P40: =IFERROR(O40/M40,"")
B41: Senior Software Engineer | C41: IN | G41: 8 | H41: =IF(D41="Yes",HLOOKUP($K$50,'Rate Card & Lookups'!$D$9:$F$39,4,FALSE)*$C$20,_xlfn.IFNA(INDEX('Rate Card & Lookups'!$D$10:$F$39,MATCH($B41&C41,'Rate Card & Lookups'!$A$10:$A$39,0),MATCH($H$30,'Rate Card & Lookups'!$D$9:$F$9,0))*$C$20,"")) -> 585 | I41: =_xlfn.IFNA(INDEX('Rate Card & Lookups'!$G$10:$I$39,MATCH($B41&C41,'Rate Card & Lookups'!$A$10:$A$39,0),MATCH($I$30,'Rate Card & Lookups'!$G$9:$I$9,0)),"") -> 58.5 | K41: =IF(ISBLANK(G41),"",G41/8) -> 1 | L41: =IFERROR(H41*K41,"") -> 585 | M41: =IFERROR(L41*J41,"") -> 0 | N41: =IFERROR(I41*K41*J41,"") -> 0 | O41: =IFERROR(M41-N41,"") -> 0 | P41: =IFERROR(O41/M41,"")
H42: =IF(D42="Yes",HLOOKUP($K$50,'Rate Card & Lookups'!$D$9:$F$39,4,FALSE)*$C$20,_xlfn.IFNA(INDEX('Rate Card & Lookups'!$D$10:$F$39,MATCH($B42&C42,'Rate Card & Lookups'!$A$10:$A$39,0),MATCH($H$30,'Rate Card & Lookups'!$D$9:$F$9,0))*$C$20,"")) | I42: =_xlfn.IFNA(INDEX('Rate Card & Lookups'!$G$10:$I$39,MATCH($B42&C42,'Rate Card & Lookups'!$A$10:$A$39,0),MATCH($I$30,'Rate Card & Lookups'!$G$9:$I$9,0)),"") | K42: =IF(ISBLANK(G42),"",G42/8) | L42: =IFERROR(H42*K42,"") | M42: =IFERROR(L42*J42,"") | N42: =IFERROR(I42*K42*J42,"") | O42: =IFERROR(M42-N42,"") | P42: =IFERROR(O42/M42,"")
H43: =IF(D43="Yes",HLOOKUP($K$50,'Rate Card & Lookups'!$D$9:$F$39,4,FALSE)*$C$20,_xlfn.IFNA(INDEX('Rate Card & Lookups'!$D$10:$F$39,MATCH($B43&C43,'Rate Card & Lookups'!$A$10:$A$39,0),MATCH($H$30,'Rate Card & Lookups'!$D$9:$F$9,0))*$C$20,"")) | I43: =_xlfn.IFNA(INDEX('Rate Card & Lookups'!$G$10:$I$39,MATCH($B43&C43,'Rate Card & Lookups'!$A$10:$A$39,0),MATCH($I$30,'Rate Card & Lookups'!$G$9:$I$9,0)),"") | K43: =IF(ISBLANK(G43),"",G43/8) | L43: =IFERROR(H43*K43,"") | M43: =IFERROR(L43*J43,"") | N43: =IFERROR(I43*K43*J43,"") | O43: =IFERROR(M43-N43,"") | P43: =IFERROR(O43/M43,"")
H44: =IF(D44="Yes",HLOOKUP($K$50,'Rate Card & Lookups'!$D$9:$F$39,4,FALSE)*$C$20,_xlfn.IFNA(INDEX('Rate Card & Lookups'!$D$10:$F$39,MATCH($B44&C44,'Rate Card & Lookups'!$A$10:$A$39,0),MATCH($H$30,'Rate Card & Lookups'!$D$9:$F$9,0))*$C$20,"")) | I44: =_xlfn.IFNA(INDEX('Rate Card & Lookups'!$G$10:$I$39,MATCH($B44&C44,'Rate Card & Lookups'!$A$10:$A$39,0),MATCH($I$30,'Rate Card & Lookups'!$G$9:$I$9,0)),"") | K44: =IF(ISBLANK(G44),"",G44/8) | L44: =IFERROR(H44*K44,"") | M44: =IFERROR(L44*J44,"") | N44: =IFERROR(I44*K44*J44,"") | O44: =IFERROR(M44-N44,"") | P44: =IFERROR(O44/M44,"")
H45: =IF(D45="Yes",HLOOKUP($K$50,'Rate Card & Lookups'!$D$9:$F$39,4,FALSE)*$C$20,_xlfn.IFNA(INDEX('Rate Card & Lookups'!$D$10:$F$39,MATCH($B45&C45,'Rate Card & Lookups'!$A$10:$A$39,0),MATCH($H$30,'Rate Card & Lookups'!$D$9:$F$9,0))*$C$20,"")) | I45: =_xlfn.IFNA(INDEX('Rate Card & Lookups'!$G$10:$I$39,MATCH($B45&C45,'Rate Card & Lookups'!$A$10:$A$39,0),MATCH($I$30,'Rate Card & Lookups'!$G$9:$I$9,0)),"") | K45: =IF(ISBLANK(G45),"",G45/8) | L45: =IFERROR(H45*K45,"") | M45: =IFERROR(L45*J45,"") | N45: =IFERROR(I45*K45*J45,"") | O45: =IFERROR(M45-N45,"") | P45: =IFERROR(O45/M45,"")
H46: =IF(D46="Yes",HLOOKUP($K$50,'Rate Card & Lookups'!$D$9:$F$39,4,FALSE)*$C$20,_xlfn.IFNA(INDEX('Rate Card & Lookups'!$D$10:$F$39,MATCH($B46&C46,'Rate Card & Lookups'!$A$10:$A$39,0),MATCH($H$30,'Rate Card & Lookups'!$D$9:$F$9,0))*$C$20,"")) | I46: =_xlfn.IFNA(INDEX('Rate Card & Lookups'!$G$10:$I$39,MATCH($B46&C46,'Rate Card & Lookups'!$A$10:$A$39,0),MATCH($I$30,'Rate Card & Lookups'!$G$9:$I$9,0)),"") | K46: =IF(ISBLANK(G46),"",G46/8) | L46: =IFERROR(H46*K46,"") | M46: =IFERROR(L46*J46,"") | N46: =IFERROR(I46*K46*J46,"") | O46: =IFERROR(M46-N46,"") | P46: =IFERROR(O46/M46,"")
H47: =IF(D47="Yes",HLOOKUP($K$50,'Rate Card & Lookups'!$D$9:$F$39,4,FALSE)*$C$20,_xlfn.IFNA(INDEX('Rate Card & Lookups'!$D$10:$F$39,MATCH($B47&C47,'Rate Card & Lookups'!$A$10:$A$39,0),MATCH($H$30,'Rate Card & Lookups'!$D$9:$F$9,0))*$C$20,"")) | I47: =_xlfn.IFNA(INDEX('Rate Card & Lookups'!$G$10:$I$39,MATCH($B47&C47,'Rate Card & Lookups'!$A$10:$A$39,0),MATCH($I$30,'Rate Card & Lookups'!$G$9:$I$9,0)),"") | K47: =IF(ISBLANK(G47),"",G47/8) | L47: =IFERROR(H47*K47,"") | M47: =IFERROR(L47*J47,"") | N47: =IFERROR(I47*K47*J47,"") | O47: =IFERROR(M47-N47,"") | P47: =IFERROR(O47/M47,"")
H48: =IF(D48="Yes",HLOOKUP($K$50,'Rate Card & Lookups'!$D$9:$F$39,4,FALSE)*$C$20,_xlfn.IFNA(INDEX('Rate Card & Lookups'!$D$10:$F$39,MATCH($B48&C48,'Rate Card & Lookups'!$A$10:$A$39,0),MATCH($H$30,'Rate Card & Lookups'!$D$9:$F$9,0))*$C$20,"")) | I48: =_xlfn.IFNA(INDEX('Rate Card & Lookups'!$G$10:$I$39,MATCH($B48&C48,'Rate Card & Lookups'!$A$10:$A$39,0),MATCH($I$30,'Rate Card & Lookups'!$G$9:$I$9,0)),"") | K48: =IF(ISBLANK(G48),"",G48/8) | L48: =IFERROR(H48*K48,"") | M48: =IFERROR(L48*J48,"") | N48: =IFERROR(I48*K48*J48,"") | O48: =IFERROR(M48-N48,"") | P48: =IFERROR(O48/M48,"")
...

Sheet Rate Card & Lookups
B2: Rate Cards
G7: FX rate: | H7: 1.3 | I7: 1.2
D8: Customer Billing Country / Currency | G8: Cost rates | Y8: Holidays
B9: Role | C9: Employee Location | D9: GBP | E9: USD | F9: EUR | G9: GBP | H9: USD | I9: EUR | J9: Conversion US Cust | K9: Conversion EU Cust | M9: Engagement style | O9: Project Type | P9: Multiplier | R9: Employee Location | T9: Customer Geography | U9: Billing Currency | W9: Role | Y9: UK | Z9: USA | AA9: IN | AC9: Discount Reason | AD9: Discount Lower Limit | AE9: Discount Upper Limit | AG9: Yes/no drop down | AI9: Payment terms | AJ9: Premium
A10: =B10&C10 -> Associate PartnerUK | B10: Associate Partner | C10: UK | D10: 2250 | E10: 3526.25 | F10: =D10*$I$7 -> 2700 | G10: 1145 | H10: =G10*$H$7 -> 1488.5 | I10: =G10*$I$7 -> 1374 | J10: =E10/D10 -> 1.5672222 | K10: =F10/D10 -> 1.2 | M10: Project | O10: Core Reporting | P10: 1 | R10: IN | T10: Other | U10: GBP | W10: Partner | Y10: =DATE(2024,3,29) -> 45380 | Z10: =DATE(2023,12,25) -> 45285 | AA10: =DATE(2024,1,15) -> 45306 | AC10: Long duration engagement (Secondments & MS, guidance: 6-12 months 5%, 12+ months 10%) | AD10: 0 | AE10: -0.1 | AG10: Yes | AI10: JMAN standard (EOM + 20 days) | AJ10: 0
A11: =B11&C11 -> PrincipalUK | B11: Principal | C11: UK | D11: 1950 | E11: 3233.75 | F11: =D11*$I$7 -> 2340 | G11: 780 | H11: =G11*$H$7 -> 1014 | I11: =G11*$I$7 -> 936 | J11: =E11/D11 -> 1.6583333 | K11: =F11/D11 -> 1.2 | M11: Secondment | O11: Data Advisory | P11: 1 | R11: Other | T11: UK | U11: GBP | W11: Associate Partner | Y11: =DATE(2024,4,1) -> 45383 | Z11: =DATE(2023,1,1) -> 44927 | AA11: =DATE(2024,1,26) -> 45317 | AC11: First project with new client | AD11: 0 | AE11: -0.3 | AG11: No | AI11: EOM + 30 days | AJ11: 0
A12: =B12&C12 -> ManagerUK | B12: Manager | C12: UK | D12: 1750 | E12: 2983.5 | F12: =D12*$I$7 -> 2100 | G12: 585 | H12: =G12*$H$7 -> 760.5 | I12: =G12*$I$7 -> 702 | J12: =E12/D12 -> 1.7048571 | K12: =F12/D12 -> 1.2 | M12: Managed Services | O12: Due Diligence | P12: 1 | R12: UK | T12: USA | U12: USD | W12: Principal | Y12: =DATE(2024,5,6) -> 45418 | AA12: =DATE(2024,4,11) -> 45393 | AC12: Strategic Opportunity - New project type or High value project for JMAN | AD12: 0 | AE12: -0.2 | AI12: EOM + 60 days | AJ12: 0.025
A13: =B13&C13 -> Senior ConsultantUK | B13: Senior Consultant | C13: UK | D13: 1500 | E13: 2798.25 | F13: =D13*$I$7 -> 1800 | G13: 480 | H13: =G13*$H$7 -> 624 | I13: =G13*$I$7 -> 576 | J13: =E13/D13 -> 1.8655 | K13: =F13/D13 -> 1.2 | O13: Exit Support | P13: 1 | R13: USA | T13: Europe | U13: EUR | W13: Manager | Y13: =DATE(2024,5,27) -> 45439 | AA13: =DATE(2024,5,1) -> 45413 | AC13: Managing price increase for existing clients | AD13: 0 | AE13: -0.2 | AI13: EOM + 90 days | AJ13: =AJ12*2 -> 0.05
A14: =B14&C14 -> ConsultantUK | B14: Consultant | C14: UK | D14: 1350 | E14: 2457 | F14: =D14*$I$7 -> 1620 | G14: 425 | H14: =G14*$H$7 -> 552.5 | I14: =G14*$I$7 -> 510 | J14: =E14/D14 -> 1.82 | K14: =F14/D14 -> 1.2 | O14: Managed Services | P14: 1 | W14: Senior Consultant | Y14: =DATE(2024,8,26) -> 45530 | AA14: =DATE(2024,8,15) -> 45519 | AC14: Improve lagging client relationship | AD14: 0 | AE14: -0.2
A15: =B15&C15 -> Senior Associate ConsultantUK | B15: Senior Associate Consultant | C15: UK | D15: 1100 | E15: 1979.25 | F15: =D15*$I$7 -> 1320 | G15: 335 | H15: =G15*$H$7 -> 435.5 | I15: =G15*$I$7 -> 402 | J15: =E15/D15 -> 1.7993182 | K15: =F15/D15 -> 1.2 | O15: Other | P15: 1 | W15: Consultant | Y15: =DATE(2023,12,25) -> 45285 | AA15: =DATE(2024,10,2) -> 45567 | AC15: Projects for charity/ pro bono projects | AD15: 0 | AE15: -1
A16: =B16&C16 -> Associate ConsultantUK | B16: Associate Consultant | C16: UK | D16: 975 | E16: 1865.5 | F16: =D16*$I$7 -> 1170 | G16: 290 | H16: =G16*$H$7 -> 377 | I16: =G16*$I$7 -> 348 | J16: =E16/D16 -> 1.9133333 | K16: =F16/D16 -> 1.2 | O16: Value Creation | P16: 1 | W16: Senior Associate Consultant | Y16: =DATE(2024,12,26) -> 45652 | AA16: =DATE(2024,10,31) -> 45596 | AC16: Other situation (please specify) | AE16: -0.2
A17: =B17&C17 -> InternUK | B17: Intern | C17: UK | D17: 975 | E17: 1865.5 | F17: =D17*$I$7 -> 1170 | G17: 220 | H17: =G17*$H$7 -> 286 | I17: =G17*$I$7 -> 264 | J17: =E17/D17 -> 1.9133333 | K17: =F17/D17 -> 1.2 | W17: Associate Consultant | AA17: =DATE(2024,12,25) -> 45651
A18: =B18&C18 -> Senior Solutions ConsultantUK | B18: Senior Solutions Consultant | C18: UK | D18: 1500 | E18: =E13 -> 2798.25 | F18: =D18*$I$7 -> 1800 | G18: 485 | H18: =G18*$H$7 -> 630.5 | I18: =G18*$I$7 -> 582 | J18: =E18/D18 -> 1.8655 | K18: =F18/D18 -> 1.2 | W18: Intern | AC18: Effective maximum | AE18: =VLOOKUP(#REF!,'Rate Card & Lookups'!$AC$10:$AE$16,3,FALSE)*100 -> #REF! | AF18: %
A19: =B19&C19 -> Solutions ConsultantUK | B19: Solutions Consultant | C19: UK | D19: 1350 | E19: =E14 -> 2457 | F19: =D19*$I$7 -> 1620 | G19: 440 | H19: =G19*$H$7 -> 572 | I19: =G19*$I$7 -> 528 | J19: =E19/D19 -> 1.82 | K19: =F19/D19 -> 1.2 | W19: Partner Technology
A20: =B20&C20 -> Principal Technology ArchitectIN | B20: Principal Technology Architect | C20: IN | D20: 650 | E20: =D20*$H$7 -> 845 | F20: =D20*$I$7 -> 780 | G20: 230 | H20: =G20*$H$7 -> 299 | I20: =G20*$I$7 -> 276 | J20: =E20/D20 -> 1.3 | K20: =F20/D20 -> 1.2 | W20: Associate Partner Technology
A21: =B21&C21 -> Technical Solutions ArchitectIN | B21: Technical Solutions Architect | C21: IN | D21: 575 | E21: =D21*$H$7 -> 747.5 | F21: =D21*$I$7 -> 690 | G21: 140 | H21: =G21*$H$7 -> 182 | I21: =G21*$I$7 -> 168 | J21: =E21/D21 -> 1.3 | K21: =F21/D21 -> 1.2 | W21: Principal Technology Architect
A22: =B22&C22 -> Senior Solutions ConsultantIN | B22: Senior Solutions Consultant | C22: IN | D22: 550 | E22: =D22*$H$7 -> 715 | F22: =D22*$I$7 -> 660 | G22: 110 | H22: =G22*$H$7 -> 143 | I22: =G22*$I$7 -> 132 | J22: =E22/D22 -> 1.3 | K22: =F22/D22 -> 1.2 | W22: Technical Solutions Architect
A23: =B23&C23 -> Solutions ConsultantIN | B23: Solutions Consultant | C23: IN | D23: 525 | E23: =D23*$H$7 -> 682.5 | F23: =D23*$I$7 -> 630 | G23: 85 | H23: =G23*$H$7 -> 110.5 | I23: =G23*$I$7 -> 102 | J23: =E23/D23 -> 1.3 | K23: =F23/D23 -> 1.2 | W23: Senior Solutions Consultant
A24: =B24&C24 -> Solutions EnablerIN | B24: Solutions Enabler | C24: IN | D24: 525 | E24: =D24*$H$7 -> 682.5 | F24: =D24*$I$7 -> 630 | G24: 65 | H24: =G24*$H$7 -> 84.5 | I24: =G24*$I$7 -> 78 | J24: =E24/D24 -> 1.3 | K24: =F24/D24 -> 1.2 | W24: Solutions Consultant
A25: =B25&C25 -> Senior Software EngineerIN | B25: Senior Software Engineer | C25: IN | D25: 450 | E25: =D25*$H$7 -> 585 | F25: =D25*$I$7 -> 540 | G25: 45 | H25: =G25*$H$7 -> 58.5 | I25: =G25*$I$7 -> 54 | J25: =E25/D25 -> 1.3 | K25: =F25/D25 -> 1.2 | W25: Solutions Enabler
A26: =B26&C26 -> Software EngineerIN | B26: Software Engineer | C26: IN | D26: 350 | E26: =D26*$H$7 -> 455 | F26: =D26*$I$7 -> 420 | G26: 35 | H26: =G26*$H$7 -> 45.5 | I26: =G26*$I$7 -> 42 | J26: =E26/D26 -> 1.3 | K26: =F26/D26 -> 1.2 | W26: Senior Software Engineer
A27: =B27&C27 -> Intern TechnologyIN | B27: Intern Technology | C27: IN | D27: 300 | E27: =D27*$H$7 -> 390 | F27: =D27*$I$7 -> 360 | G27: 20 | H27: =G27*$H$7 -> 26 | I27: =G27*$I$7 -> 24 | J27: =E27/D27 -> 1.3 | K27: =F27/D27 -> 1.2 | W27: Software Engineer
A28: =B28&C28 -> ConsultantIN | B28: Consultant | C28: IN | D28: 525 | E28: =D28*$H$7 -> 682.5 | F28: =D28*$I$7 -> 630 | G28: 70 | H28: =G28*$H$7 -> 91 | I28: =G28*$I$7 -> 84 | J28: =E28/D28 -> 1.3 | K28: =F28/D28 -> 1.2 | W28: Intern Technology
A29: =B29&C29 -> Senior Associate ConsultantIN | B29: Senior Associate Consultant | C29: IN | D29: 525 | E29: =D29*$H$7 -> 682.5 | F29: =D29*$I$7 -> 630 | G29: 55 | H29: =G29*$H$7 -> 71.5 | I29: =G29*$I$7 -> 66 | J29: =E29/D29 -> 1.3 | K29: =F29/D29 -> 1.2
A30: =B30&C30 -> Associate ConsultantIN | B30: Associate Consultant | C30: IN | D30: 450 | E30: =D30*$H$7 -> 585 | F30: =D30*$I$7 -> 540 | G30: 45 | H30: =G30*$H$7 -> 58.5 | I30: =G30*$I$7 -> 54 | J30: =E30/D30 -> 1.3 | K30: =F30/D30 -> 1.2
A31: =B31&C31 -> Associate PartnerUSA | B31: Associate Partner | C31: USA | D31: 2712.5 | E31: =E10 -> 3526.25 | F31: =D31*$I$7 -> 3255 | G31: 1345 | H31: =G31*$H$7 -> 1748.5 | I31: =H31*$H$7/$I$7 -> 1894.2083 | J31: =E31/D31 -> 1.3 | K31: =F31/D31 -> 1.2
A32: =B32&C32 -> PrincipalUSA | B32: Principal | C32: USA | D32: 2487.5 | E32: =E11 -> 3233.75 | F32: =D32*$I$7 -> 2985 | G32: 945 | H32: =G32*$H$7 -> 1228.5 | I32: =H32*$H$7/$I$7 -> 1330.875 | J32: =E32/D32 -> 1.3 | K32: =F32/D32 -> 1.2
A33: =B33&C33 -> ManagerUSA | B33: Manager | C33: USA | D33: 2295 | E33: =E12 -> 2983.5 | F33: =D33*$I$7 -> 2754 | G33: 790 | H33: =G33*$H$7 -> 1027 | I33: =H33*$H$7/$I$7 -> 1112.5833 | J33: =E33/D33 -> 1.3 | K33: =F33/D33 -> 1.2
A34: =B34&C34 -> Senior ConsultantUSA | B34: Senior Consultant | C34: USA | D34: 2152.5 | E34: =E13 -> 2798.25 | F34: =D34*$I$7 -> 2583 | G34: 640 | H34: =G34*$H$7 -> 832 | I34: =H34*$H$7/$I$7 -> 901.33333 | J34: =E34/D34 -> 1.3 | K34: =F34/D34 -> 1.2
A35: =B35&C35 -> ConsultantUSA | B35: Consultant | C35: USA | D35: 1890 | E35: =E14 -> 2457 | F35: =D35*$I$7 -> 2268 | G35: 560 | H35: =G35*$H$7 -> 728 | I35: =H35*$H$7/$I$7 -> 788.66667 | J35: =E35/D35 -> 1.3 | K35: =F35/D35 -> 1.2
A36: =B36&C36 -> Senior Associate ConsultantUSA | B36: Senior Associate Consultant | C36: USA | D36: 1522.5 | E36: =E15 -> 1979.25 | F36: =D36*$I$7 -> 1827 | G36: 450 | H36: =G36*$H$7 -> 585 | I36: =H36*$H$7/$I$7 -> 633.75 | J36: =E36/D36 -> 1.3 | K36: =F36/D36 -> 1.2
A37: =B37&C37 -> Associate ConsultantUSA | B37: Associate Consultant | C37: USA | D37: 1435 | E37: =E16 -> 1865.5 | F37: =D37*$I$7 -> 1722 | G37: 425 | H37: =G37*$H$7 -> 552.5 | I37: =H37*$H$7/$I$7 -> 598.54167 | J37: =E37/D37 -> 1.3 | K37: =F37/D37 -> 1.2
A38: =B38&C38 -> InternUSA | B38: Intern | C38: USA | D38: 1435 | E38: =E17 -> 1865.5 | F38: =D38*$I$7 -> 1722 | G38: 365 | H38: =G38*$H$7 -> 474.5 | I38: =H38*$H$7/$I$7 -> 514.04167 | J38: =E38/D38 -> 1.3 | K38: =F38/D38 -> 1.2
A39: =B39&C39 -> Technical Solutions ArchitectUSA | B39: Technical Solutions Architect | C39: USA | D39: 2487.5 | E39: =D39*$H$7 -> 3233.75 | F39: =D39*$I$7 -> 2985 | G39: 955 | H39: =G39*$H$7 -> 1241.5 | I39: =H39*$H$7/$I$7 -> 1344.9583 | J39: =E39/D39 -> 1.3 | K39: =F39/D39 -> 1.2
B42: Managed Services out-of-hour premium
B43: 0.03
