Workbook

Sheet README
A1: 6-Month Cluster Revenue & COE Demand-Supply Forecast
A2: Built from: Pipeline Details, Skill Data, Employee Details, Project Allocation Details
A4: HOW THIS MODEL WORKS
A5: 1. Revenue_Trend tab: Total company revenue for Jan-Jun 2026 (given) is trended forward with FORECAST.LINEAR to get a top-down TOTAL revenue estimate for Jul-Dec 2026.
A6: 2. Pipeline_Data tab: Every open pipeline deal/role line (Pipeline Details > Forecast tab) is cleaned, mapped to a rate-card role, and its revenue is spread across the months it runs using day-count proration.
A7: 3. Cluster_Forecast tab: The bottom-up pipeline revenue is used only to work out each Cluster's % SHARE of business each month (since Cluster is only tagged in the pipeline, not in historical actuals). That % share is then applied to the top-down TOTAL revenue trend from step 1. This is the blend the user requested: 'get the forecasted revenue from previous data and spread that revenue based on the cluster achievable %s in the pipeline'.
A8: 4. COE_Supply_Demand tab: Pipeline role requests are mapped to a Centre of Excellence (COE) to estimate DEMAND headcount by COE by month. SUPPLY is active headcount by COE (from Skill Data + Employee Details) minus employees already billable on confirmed projects (from Project Allocation Details).
A10: KEY ASSUMPTIONS - PLEASE REVIEW & EDIT (blue cells)
A11: - Rate_Card and Role_Mapping tabs are editable assumption tables (blue font = input). Pipeline role codes (e.g. 'SC', 'PA', 'Sr DS SME') are mapped to a standard role/location/COE using best-fit judgement - please correct any mapping that looks wrong.
A12: - Deal duration/allocation values with unusual formats in the source (e.g. '75/100', '25-50') were averaged. Rows missing a duration were defaulted to the pipeline's median duration.
A13: - Cluster is not tagged anywhere in the 3-years-of-actuals data provided, only in the future pipeline. This is why the model blends top-down total trend x bottom-up cluster mix, rather than trending each cluster's history directly. If a project-level table with Cluster + Project Type (Internal/BAU/Sales) + monthly revenue becomes available, that should replace this workaround with a direct per-cluster trend/FORECAST.ETS.
A14: - 'Internal / BAU / Sales' project exclusion could not be applied because no project-type field exists in any of the 5 source files - the pipeline tab used here only contains client opportunities, so no explicit exclusion was needed for the bottom-up piece.
... A16: - Only 286 of 665 active employees have a recorded Skill/COE tag in Skill Data; Supply figures reflect only that mapped population - flagged in the COE tab.

Sheet Rate_Card
A1: Role Rate Card (USD Day Rate) - Source: Client Rate Card screenshot
A2: Blue cells = editable inputs. Used by Pipeline_Data to price each pipeline role request.
A4: Role | B4: Location | C4: Day Rate (USD)
A5: Associate Partner | B5: UK | C5: 3526
A6: Principal | B6: UK | C6: 3234
A7: Manager | B7: UK | C7: 2984
A8: Senior Consultant | B8: UK | C8: 2798
A9: Consultant | B9: UK | C9: 2457
A10: Senior Associate Consultant | B10: UK | C10: 1979
A11: Associate Consultant | B11: UK | C11: 1866
A12: Intern | B12: UK | C12: 1866
A13: Senior Solutions Consultant | B13: UK | C13: 2798
A14: Solutions Consultant | B14: UK | C14: 2457
A15: Principal Technology Architect | B15: IN | C15: 845
A16: Technical Solutions Architect | B16: IN | C16: 748
... A34: Technical Solutions Architect | B34: USA | C34: 3234

Sheet Role_Mapping
A1: Pipeline Role-Code Mapping (ASSUMPTION - please review/correct)
A2: Maps each 'Resources Requested' code from Pipeline Details > Forecast to a Rate_Card role, a default location, and a Skill-Data COE.
A4: Pipeline Role Code | B4: Mapped Role (Rate_Card) | C4: Default Location | D4: Mapped COE | E4: Confidence
A5: AC | B5: Associate Consultant | C5: IN | D5: Consulting | E5: High
A6: AC (UK) | B6: Associate Consultant | C6: UK | D6: Consulting | E6: High
A7: AP | B7: Associate Partner | C7: UK | D7: GTM | E7: Medium
A8: AP/P | B8: Associate Partner | C8: UK | D8: GTM | E8: Medium
A9: C | B9: Consultant | C9: IN | D9: Consulting | E9: High
A10: C/SAC/AC | B10: Consultant | C10: IN | D10: Consulting | E10: Low - multi-role code, picked mid-point
A11: EM | B11: Manager | C11: UK | D11: Consulting | E11: Medium - Engagement Manager proxy
A12: Enabler | B12: Solutions Enabler | C12: IN | D12: Data Engineering | E12: Medium
A13: GTM Architect | B13: Principal Technology Architect | C13: IN | D13: GTM | E13: Medium
A14: M | B14: Manager | C14: UK | D14: Consulting | E14: High
A15: P | B15: Associate Partner | C15: UK | D15: GTM | E15: Medium - 'Partner' not separately rate-carded
... A31: Sr Sol Con | B31: Senior Solutions Consultant | C31: IN | D31: Power BI & Consulting | E31: High

Sheet Pipeline_Data
A1: Pipeline Deal-Role Lines (cleaned from Pipeline Details > Forecast) with Revenue Calculation
A2: Revenue per line = Day Rate x Working Days x Allocation% , then spread across the 6 forecast months by day-overlap proration.
A4: DealID | B4: Cluster | C4: Client | D4: RoleCode | E4: Start Date | F4: Weeks | G4: End Date | H4: Alloc % | I4: Status | J4: Mapped Role | K4: Location | L4: Day Rate (USD) | M4: Working Days | N4: Total Deal Revenue (USD) | O4: Total Days | P4: Mapped COE | Q4: Jul-2026 (Revenue) | R4: Aug-2026 (Revenue) | S4: Sep-2026 (Revenue) | T4: Oct-2026 (Revenue) | U4: Nov-2026 (Revenue) | V4: Dec-2026 (Revenue) | W4: Jul-2026 (Demand FTE) | X4: Aug-2026 (Demand FTE) | Y4: Sep-2026 (Demand FTE) | Z4: Oct-2026 (Demand FTE) | AA4: Nov-2026 (Demand FTE) | AB4: Dec-2026 (Demand FTE)
A5: 1 | B5: 3 | C5: Sigma | D5: P | E5: 46209 | F5: 11 | G5: 46286 | H5: 0.25 | I5: Not Resourced | J5: =IFERROR(VLOOKUP(D5,Role_Mapping!$A$5:$D$31,2,FALSE()),"UNMAPPED") -> Associate Partner | K5: =IFERROR(VLOOKUP(D5,Role_Mapping!$A$5:$D$31,3,FALSE()),"IN") -> UK | L5: =IFERROR(SUMPRODUCT((Rate_Card!$A$5:$A$34=J5)*(Rate_Card!$B$5:$B$34=K5)*Rate_Card!$C$5:$C$34),0) -> 3526 | M5: =F5*5 -> 55 | N5: =L5*M5*H5 -> 48482.5 | O5: =(G5-E5)+1 -> 78 | P5: =IFERROR(VLOOKUP(D5,Role_Mapping!$A$5:$D$31,4,FALSE()),"UNMAPPED") -> GTM | Q5: =$N5*MAX(0,(MIN($G5,DATE(2026,7,31))-MAX($E5,DATE(2026,7,1))+1))/$O5 -> 16160.833 | R5: =$N5*MAX(0,(MIN($G5,DATE(2026,8,31))-MAX($E5,DATE(2026,8,1))+1))/$O5 -> 19268.686 | S5: =$N5*MAX(0,(MIN($G5,DATE(2026,9,30))-MAX($E5,DATE(2026,9,1))+1))/$O5 -> 13052.981 | T5: =$N5*MAX(0,(MIN($G5,DATE(2026,10,31))-MAX($E5,DATE(2026,10,1))+1))/$O5 -> 0 | U5: =$N5*MAX(0,(MIN($G5,DATE(2026,11,30))-MAX($E5,DATE(2026,11,1))+1))/$O5 -> 0 | V5: =$N5*MAX(0,(MIN($G5,DATE(2026,12,31))-MAX($E5,DATE(2026,12,1))+1))/$O5 -> 0 | W5: =$H5*MAX(0,(MIN($G5,DATE(2026,7,31))-MAX($E5,DATE(2026,7,1))+1))/30.4 -> 0.21381579 | X5: =$H5*MAX(0,(MIN($G5,DATE(2026,8,31))-MAX($E5,DATE(2026,8,1))+1))/30.4 -> 0.25493421 | Y5: =$H5*MAX(0,(MIN($G5,DATE(2026,9,30))-MAX($E5,DATE(2026,9,1))+1))/30.4 -> 0.17269737 | Z5: =$H5*MAX(0,(MIN($G5,DATE(2026,10,31))-MAX($E5,DATE(2026,10,1))+1))/30.4 -> 0 | AA5: =$H5*MAX(0,(MIN($G5,DATE(2026,11,30))-MAX($E5,DATE(2026,11,1))+1))/30.4 -> 0 | AB5: =$H5*MAX(0,(MIN($G5,DATE(2026,12,31))-MAX($E5,DATE(2026,12,1))+1))/30.4 -> 0
A6: 1 | B6: 3 | C6: Sigma | D6: SC | E6: 46209 | F6: 11 | G6: 46286 | H6: 0.5 | I6: Not Resourced | J6: =IFERROR(VLOOKUP(D6,Role_Mapping!$A$5:$D$31,2,FALSE()),"UNMAPPED") -> Senior Consultant | K6: =IFERROR(VLOOKUP(D6,Role_Mapping!$A$5:$D$31,3,FALSE()),"IN") -> UK | L6: =IFERROR(SUMPRODUCT((Rate_Card!$A$5:$A$34=J6)*(Rate_Card!$B$5:$B$34=K6)*Rate_Card!$C$5:$C$34),0) -> 2798 | M6: =F6*5 -> 55 | N6: =L6*M6*H6 -> 76945 | O6: =(G6-E6)+1 -> 78 | P6: =IFERROR(VLOOKUP(D6,Role_Mapping!$A$5:$D$31,4,FALSE()),"UNMAPPED") -> Consulting | Q6: =$N6*MAX(0,(MIN($G6,DATE(2026,7,31))-MAX($E6,DATE(2026,7,1))+1))/$O6 -> 25648.333 | R6: =$N6*MAX(0,(MIN($G6,DATE(2026,8,31))-MAX($E6,DATE(2026,8,1))+1))/$O6 -> 30580.705 | S6: =$N6*MAX(0,(MIN($G6,DATE(2026,9,30))-MAX($E6,DATE(2026,9,1))+1))/$O6 -> 20715.962 | T6: =$N6*MAX(0,(MIN($G6,DATE(2026,10,31))-MAX($E6,DATE(2026,10,1))+1))/$O6 -> 0 | U6: =$N6*MAX(0,(MIN($G6,DATE(2026,11,30))-MAX($E6,DATE(2026,11,1))+1))/$O6 -> 0 | V6: =$N6*MAX(0,(MIN($G6,DATE(2026,12,31))-MAX($E6,DATE(2026,12,1))+1))/$O6 -> 0 | W6: =$H6*MAX(0,(MIN($G6,DATE(2026,7,31))-MAX($E6,DATE(2026,7,1))+1))/30.4 -> 0.42763158 | X6: =$H6*MAX(0,(MIN($G6,DATE(2026,8,31))-MAX($E6,DATE(2026,8,1))+1))/30.4 -> 0.50986842 | Y6: =$H6*MAX(0,(MIN($G6,DATE(2026,9,30))-MAX($E6,DATE(2026,9,1))+1))/30.4 -> 0.34539474 | Z6: =$H6*MAX(0,(MIN($G6,DATE(2026,10,31))-MAX($E6,DATE(2026,10,1))+1))/30.4 -> 0 | AA6: =$H6*MAX(0,(MIN($G6,DATE(2026,11,30))-MAX($E6,DATE(2026,11,1))+1))/30.4 -> 0 | AB6: =$H6*MAX(0,(MIN($G6,DATE(2026,12,31))-MAX($E6,DATE(2026,12,1))+1))/30.4 -> 0
A7: 1 | B7: 3 | C7: Sigma | D7: C | E7: 46209 | F7: 11 | G7: 46286 | H7: 1 | I7: Not Resourced | J7: =IFERROR(VLOOKUP(D7,Role_Mapping!$A$5:$D$31,2,FALSE()),"UNMAPPED") -> Consultant | K7: =IFERROR(VLOOKUP(D7,Role_Mapping!$A$5:$D$31,3,FALSE()),"IN") -> IN | L7: =IFERROR(SUMPRODUCT((Rate_Card!$A$5:$A$34=J7)*(Rate_Card!$B$5:$B$34=K7)*Rate_Card!$C$5:$C$34),0) -> 683 | M7: =F7*5 -> 55 | N7: =L7*M7*H7 -> 37565 | O7: =(G7-E7)+1 -> 78 | P7: =IFERROR(VLOOKUP(D7,Role_Mapping!$A$5:$D$31,4,FALSE()),"UNMAPPED") -> Consulting | Q7: =$N7*MAX(0,(MIN($G7,DATE(2026,7,31))-MAX($E7,DATE(2026,7,1))+1))/$O7 -> 12521.667 | R7: =$N7*MAX(0,(MIN($G7,DATE(2026,8,31))-MAX($E7,DATE(2026,8,1))+1))/$O7 -> 14929.679 | S7: =$N7*MAX(0,(MIN($G7,DATE(2026,9,30))-MAX($E7,DATE(2026,9,1))+1))/$O7 -> 10113.654 | T7: =$N7*MAX(0,(MIN($G7,DATE(2026,10,31))-MAX($E7,DATE(2026,10,1))+1))/$O7 -> 0 | U7: =$N7*MAX(0,(MIN($G7,DATE(2026,11,30))-MAX($E7,DATE(2026,11,1))+1))/$O7 -> 0 | V7: =$N7*MAX(0,(MIN($G7,DATE(2026,12,31))-MAX($E7,DATE(2026,12,1))+1))/$O7 -> 0 | W7: =$H7*MAX(0,(MIN($G7,DATE(2026,7,31))-MAX($E7,DATE(2026,7,1))+1))/30.4 -> 0.85526316 | X7: =$H7*MAX(0,(MIN($G7,DATE(2026,8,31))-MAX($E7,DATE(2026,8,1))+1))/30.4 -> 1.0197368 | Y7: =$H7*MAX(0,(MIN($G7,DATE(2026,9,30))-MAX($E7,DATE(2026,9,1))+1))/30.4 -> 0.69078947 | Z7: =$H7*MAX(0,(MIN($G7,DATE(2026,10,31))-MAX($E7,DATE(2026,10,1))+1))/30.4 -> 0 | AA7: =$H7*MAX(0,(MIN($G7,DATE(2026,11,30))-MAX($E7,DATE(2026,11,1))+1))/30.4 -> 0 | AB7: =$H7*MAX(0,(MIN($G7,DATE(2026,12,31))-MAX($E7,DATE(2026,12,1))+1))/30.4 -> 0
A8: 1 | B8: 3 | C8: Sigma | D8: Sr Sol Con | E8: 46209 | F8: 11 | G8: 46286 | H8: 0.875 | I8: Not Resourced | J8: =IFERROR(VLOOKUP(D8,Role_Mapping!$A$5:$D$31,2,FALSE()),"UNMAPPED") -> Senior Solutions Consultant | K8: =IFERROR(VLOOKUP(D8,Role_Mapping!$A$5:$D$31,3,FALSE()),"IN") -> IN | L8: =IFERROR(SUMPRODUCT((Rate_Card!$A$5:$A$34=J8)*(Rate_Card!$B$5:$B$34=K8)*Rate_Card!$C$5:$C$34),0) -> 715 | M8: =F8*5 -> 55 | N8: =L8*M8*H8 -> 34409.375 | O8: =(G8-E8)+1 -> 78 | P8: =IFERROR(VLOOKUP(D8,Role_Mapping!$A$5:$D$31,4,FALSE()),"UNMAPPED") -> Power BI & Consulting | Q8: =$N8*MAX(0,(MIN($G8,DATE(2026,7,31))-MAX($E8,DATE(2026,7,1))+1))/$O8 -> 11469.792 | R8: =$N8*MAX(0,(MIN($G8,DATE(2026,8,31))-MAX($E8,DATE(2026,8,1))+1))/$O8 -> 13675.521 | S8: =$N8*MAX(0,(MIN($G8,DATE(2026,9,30))-MAX($E8,DATE(2026,9,1))+1))/$O8 -> 9264.0625 | T8: =$N8*MAX(0,(MIN($G8,DATE(2026,10,31))-MAX($E8,DATE(2026,10,1))+1))/$O8 -> 0 | U8: =$N8*MAX(0,(MIN($G8,DATE(2026,11,30))-MAX($E8,DATE(2026,11,1))+1))/$O8 -> 0 | V8: =$N8*MAX(0,(MIN($G8,DATE(2026,12,31))-MAX($E8,DATE(2026,12,1))+1))/$O8 -> 0 | W8: =$H8*MAX(0,(MIN($G8,DATE(2026,7,31))-MAX($E8,DATE(2026,7,1))+1))/30.4 -> 0.74835526 | X8: =$H8*MAX(0,(MIN($G8,DATE(2026,8,31))-MAX($E8,DATE(2026,8,1))+1))/30.4 -> 0.89226974 | Y8: =$H8*MAX(0,(MIN($G8,DATE(2026,9,30))-MAX($E8,DATE(2026,9,1))+1))/30.4 -> 0.60444079 | Z8: =$H8*MAX(0,(MIN($G8,DATE(2026,10,31))-MAX($E8,DATE(2026,10,1))+1))/30.4 -> 0 | AA8: =$H8*MAX(0,(MIN($G8,DATE(2026,11,30))-MAX($E8,DATE(2026,11,1))+1))/30.4 -> 0 | AB8: =$H8*MAX(0,(MIN($G8,DATE(2026,12,31))-MAX($E8,DATE(2026,12,1))+1))/30.4 -> 0
A9: 1 | B9: 3 | C9: Sigma | D9: SSE | E9: 46209 | F9: 11 | G9: 46286 | H9: 1 | I9: Not Resourced | J9: =IFERROR(VLOOKUP(D9,Role_Mapping!$A$5:$D$31,2,FALSE()),"UNMAPPED") -> Senior Software Engineer | K9: =IFERROR(VLOOKUP(D9,Role_Mapping!$A$5:$D$31,3,FALSE()),"IN") -> IN | L9: =IFERROR(SUMPRODUCT((Rate_Card!$A$5:$A$34=J9)*(Rate_Card!$B$5:$B$34=K9)*Rate_Card!$C$5:$C$34),0) -> 585 | M9: =F9*5 -> 55 | N9: =L9*M9*H9 -> 32175 | O9: =(G9-E9)+1 -> 78 | P9: =IFERROR(VLOOKUP(D9,Role_Mapping!$A$5:$D$31,4,FALSE()),"UNMAPPED") -> Full Stack | Q9: =$N9*MAX(0,(MIN($G9,DATE(2026,7,31))-MAX($E9,DATE(2026,7,1))+1))/$O9 -> 10725 | R9: =$N9*MAX(0,(MIN($G9,DATE(2026,8,31))-MAX($E9,DATE(2026,8,1))+1))/$O9 -> 12787.5 | S9: =$N9*MAX(0,(MIN($G9,DATE(2026,9,30))-MAX($E9,DATE(2026,9,1))+1))/$O9 -> 8662.5 | T9: =$N9*MAX(0,(MIN($G9,DATE(2026,10,31))-MAX($E9,DATE(2026,10,1))+1))/$O9 -> 0 | U9: =$N9*MAX(0,(MIN($G9,DATE(2026,11,30))-MAX($E9,DATE(2026,11,1))+1))/$O9 -> 0 | V9: =$N9*MAX(0,(MIN($G9,DATE(2026,12,31))-MAX($E9,DATE(2026,12,1))+1))/$O9 -> 0 | W9: =$H9*MAX(0,(MIN($G9,DATE(2026,7,31))-MAX($E9,DATE(2026,7,1))+1))/30.4 -> 0.85526316 | X9: =$H9*MAX(0,(MIN($G9,DATE(2026,8,31))-MAX($E9,DATE(2026,8,1))+1))/30.4 -> 1.0197368 | Y9: =$H9*MAX(0,(MIN($G9,DATE(2026,9,30))-MAX($E9,DATE(2026,9,1))+1))/30.4 -> 0.69078947 | Z9: =$H9*MAX(0,(MIN($G9,DATE(2026,10,31))-MAX($E9,DATE(2026,10,1))+1))/30.4 -> 0 | AA9: =$H9*MAX(0,(MIN($G9,DATE(2026,11,30))-MAX($E9,DATE(2026,11,1))+1))/30.4 -> 0 | AB9: =$H9*MAX(0,(MIN($G9,DATE(2026,12,31))-MAX($E9,DATE(2026,12,1))+1))/30.4 -> 0
A10: 1 | B10: 3 | C10: Sigma | D10: SE | E10: 46209 | F10: 11 | G10: 46286 | H10: 1 | I10: Not Resourced | J10: =IFERROR(VLOOKUP(D10,Role_Mapping!$A$5:$D$31,2,FALSE()),"UNMAPPED") -> Software Engineer | K10: =IFERROR(VLOOKUP(D10,Role_Mapping!$A$5:$D$31,3,FALSE()),"IN") -> IN | L10: =IFERROR(SUMPRODUCT((Rate_Card!$A$5:$A$34=J10)*(Rate_Card!$B$5:$B$34=K10)*Rate_Card!$C$5:$C$34),0) -> 455 | M10: =F10*5 -> 55 | N10: =L10*M10*H10 -> 25025 | O10: =(G10-E10)+1 -> 78 | P10: =IFERROR(VLOOKUP(D10,Role_Mapping!$A$5:$D$31,4,FALSE()),"UNMAPPED") -> Full Stack | Q10: =$N10*MAX(0,(MIN($G10,DATE(2026,7,31))-MAX($E10,DATE(2026,7,1))+1))/$O10 -> 8341.6667 | R10: =$N10*MAX(0,(MIN($G10,DATE(2026,8,31))-MAX($E10,DATE(2026,8,1))+1))/$O10 -> 9945.8333 | S10: =$N10*MAX(0,(MIN($G10,DATE(2026,9,30))-MAX($E10,DATE(2026,9,1))+1))/$O10 -> 6737.5 | T10: =$N10*MAX(0,(MIN($G10,DATE(2026,10,31))-MAX($E10,DATE(2026,10,1))+1))/$O10 -> 0 | U10: =$N10*MAX(0,(MIN($G10,DATE(2026,11,30))-MAX($E10,DATE(2026,11,1))+1))/$O10 -> 0 | V10: =$N10*MAX(0,(MIN($G10,DATE(2026,12,31))-MAX($E10,DATE(2026,12,1))+1))/$O10 -> 0 | W10: =$H10*MAX(0,(MIN($G10,DATE(2026,7,31))-MAX($E10,DATE(2026,7,1))+1))/30.4 -> 0.85526316 | X10: =$H10*MAX(0,(MIN($G10,DATE(2026,8,31))-MAX($E10,DATE(2026,8,1))+1))/30.4 -> 1.0197368 | Y10: =$H10*MAX(0,(MIN($G10,DATE(2026,9,30))-MAX($E10,DATE(2026,9,1))+1))/30.4 -> 0.69078947 | Z10: =$H10*MAX(0,(MIN($G10,DATE(2026,10,31))-MAX($E10,DATE(2026,10,1))+1))/30.4 -> 0 | AA10: =$H10*MAX(0,(MIN($G10,DATE(2026,11,30))-MAX($E10,DATE(2026,11,1))+1))/30.4 -> 0 | AB10: =$H10*MAX(0,(MIN($G10,DATE(2026,12,31))-MAX($E10,DATE(2026,12,1))+1))/30.4 -> 0
A11: 2 | B11: 5 | C11: Spidy | D11: Enabler | E11: 46209 | F11: 4 | G11: 46237 | H11: 0.125 | I11: Not Resourced | J11: =IFERROR(VLOOKUP(D11,Role_Mapping!$A$5:$D$31,2,FALSE()),"UNMAPPED") -> Solutions Enabler | K11: =IFERROR(VLOOKUP(D11,Role_Mapping!$A$5:$D$31,3,FALSE()),"IN") -> IN | L11: =IFERROR(SUMPRODUCT((Rate_Card!$A$5:$A$34=J11)*(Rate_Card!$B$5:$B$34=K11)*Rate_Card!$C$5:$C$34),0) -> 683 | M11: =F11*5 -> 20 | N11: =L11*M11*H11 -> 1707.5 | O11: =(G11-E11)+1 -> 29 | P11: =IFERROR(VLOOKUP(D11,Role_Mapping!$A$5:$D$31,4,FALSE()),"UNMAPPED") -> Data Engineering | Q11: =$N11*MAX(0,(MIN($G11,DATE(2026,7,31))-MAX($E11,DATE(2026,7,1))+1))/$O11 -> 1530.8621 | R11: =$N11*MAX(0,(MIN($G11,DATE(2026,8,31))-MAX($E11,DATE(2026,8,1))+1))/$O11 -> 176.63793 | S11: =$N11*MAX(0,(MIN($G11,DATE(2026,9,30))-MAX($E11,DATE(2026,9,1))+1))/$O11 -> 0 | T11: =$N11*MAX(0,(MIN($G11,DATE(2026,10,31))-MAX($E11,DATE(2026,10,1))+1))/$O11 -> 0 | U11: =$N11*MAX(0,(MIN($G11,DATE(2026,11,30))-MAX($E11,DATE(2026,11,1))+1))/$O11 -> 0 | V11: =$N11*MAX(0,(MIN($G11,DATE(2026,12,31))-MAX($E11,DATE(2026,12,1))+1))/$O11 -> 0 | W11: =$H11*MAX(0,(MIN($G11,DATE(2026,7,31))-MAX($E11,DATE(2026,7,1))+1))/30.4 -> 0.10690789 | X11: =$H11*MAX(0,(MIN($G11,DATE(2026,8,31))-MAX($E11,DATE(2026,8,1))+1))/30.4 -> 0.012335526 | Y11: =$H11*MAX(0,(MIN($G11,DATE(2026,9,30))-MAX($E11,DATE(2026,9,1))+1))/30.4 -> 0 | Z11: =$H11*MAX(0,(MIN($G11,DATE(2026,10,31))-MAX($E11,DATE(2026,10,1))+1))/30.4 -> 0 | AA11: =$H11*MAX(0,(MIN($G11,DATE(2026,11,30))-MAX($E11,DATE(2026,11,1))+1))/30.4 -> 0 | AB11: =$H11*MAX(0,(MIN($G11,DATE(2026,12,31))-MAX($E11,DATE(2026,12,1))+1))/30.4 -> 0
A12: 2 | B12: 5 | C12: Spidy | D12: Sol Con | E12: 46209 | F12: 4 | G12: 46237 | H12: 0.5 | I12: Not Resourced | J12: =IFERROR(VLOOKUP(D12,Role_Mapping!$A$5:$D$31,2,FALSE()),"UNMAPPED") -> Solutions Consultant | K12: =IFERROR(VLOOKUP(D12,Role_Mapping!$A$5:$D$31,3,FALSE()),"IN") -> IN | L12: =IFERROR(SUMPRODUCT((Rate_Card!$A$5:$A$34=J12)*(Rate_Card!$B$5:$B$34=K12)*Rate_Card!$C$5:$C$34),0) -> 683 | M12: =F12*5 -> 20 | N12: =L12*M12*H12 -> 6830 | O12: =(G12-E12)+1 -> 29 | P12: =IFERROR(VLOOKUP(D12,Role_Mapping!$A$5:$D$31,4,FALSE()),"UNMAPPED") -> Power BI & Consulting | Q12: =$N12*MAX(0,(MIN($G12,DATE(2026,7,31))-MAX($E12,DATE(2026,7,1))+1))/$O12 -> 6123.4483 | R12: =$N12*MAX(0,(MIN($G12,DATE(2026,8,31))-MAX($E12,DATE(2026,8,1))+1))/$O12 -> 706.55172 | S12: =$N12*MAX(0,(MIN($G12,DATE(2026,9,30))-MAX($E12,DATE(2026,9,1))+1))/$O12 -> 0 | T12: =$N12*MAX(0,(MIN($G12,DATE(2026,10,31))-MAX($E12,DATE(2026,10,1))+1))/$O12 -> 0 | U12: =$N12*MAX(0,(MIN($G12,DATE(2026,11,30))-MAX($E12,DATE(2026,11,1))+1))/$O12 -> 0 | V12: =$N12*MAX(0,(MIN($G12,DATE(2026,12,31))-MAX($E12,DATE(2026,12,1))+1))/$O12 -> 0 | W12: =$H12*MAX(0,(MIN($G12,DATE(2026,7,31))-MAX($E12,DATE(2026,7,1))+1))/30.4 -> 0.42763158 | X12: =$H12*MAX(0,(MIN($G12,DATE(2026,8,31))-MAX($E12,DATE(2026,8,1))+1))/30.4 -> 0.049342105 | Y12: =$H12*MAX(0,(MIN($G12,DATE(2026,9,30))-MAX($E12,DATE(2026,9,1))+1))/30.4 -> 0 | Z12: =$H12*MAX(0,(MIN($G12,DATE(2026,10,31))-MAX($E12,DATE(2026,10,1))+1))/30.4 -> 0 | AA12: =$H12*MAX(0,(MIN($G12,DATE(2026,11,30))-MAX($E12,DATE(2026,11,1))+1))/30.4 -> 0 | AB12: =$H12*MAX(0,(MIN($G12,DATE(2026,12,31))-MAX($E12,DATE(2026,12,1))+1))/30.4 -> 0
A13: 2 | B13: 5 | C13: Spidy | D13: SE | E13: 46209 | F13: 4 | G13: 46237 | H13: 1 | I13: Not Resourced | J13: =IFERROR(VLOOKUP(D13,Role_Mapping!$A$5:$D$31,2,FALSE()),"UNMAPPED") -> Software Engineer | K13: =IFERROR(VLOOKUP(D13,Role_Mapping!$A$5:$D$31,3,FALSE()),"IN") -> IN | L13: =IFERROR(SUMPRODUCT((Rate_Card!$A$5:$A$34=J13)*(Rate_Card!$B$5:$B$34=K13)*Rate_Card!$C$5:$C$34),0) -> 455 | M13: =F13*5 -> 20 | N13: =L13*M13*H13 -> 9100 | O13: =(G13-E13)+1 -> 29 | P13: =IFERROR(VLOOKUP(D13,Role_Mapping!$A$5:$D$31,4,FALSE()),"UNMAPPED") -> Full Stack | Q13: =$N13*MAX(0,(MIN($G13,DATE(2026,7,31))-MAX($E13,DATE(2026,7,1))+1))/$O13 -> 8158.6207 | R13: =$N13*MAX(0,(MIN($G13,DATE(2026,8,31))-MAX($E13,DATE(2026,8,1))+1))/$O13 -> 941.37931 | S13: =$N13*MAX(0,(MIN($G13,DATE(2026,9,30))-MAX($E13,DATE(2026,9,1))+1))/$O13 -> 0 | T13: =$N13*MAX(0,(MIN($G13,DATE(2026,10,31))-MAX($E13,DATE(2026,10,1))+1))/$O13 -> 0 | U13: =$N13*MAX(0,(MIN($G13,DATE(2026,11,30))-MAX($E13,DATE(2026,11,1))+1))/$O13 -> 0 | V13: =$N13*MAX(0,(MIN($G13,DATE(2026,12,31))-MAX($E13,DATE(2026,12,1))+1))/$O13 -> 0 | W13: =$H13*MAX(0,(MIN($G13,DATE(2026,7,31))-MAX($E13,DATE(2026,7,1))+1))/30.4 -> 0.85526316 | X13: =$H13*MAX(0,(MIN($G13,DATE(2026,8,31))-MAX($E13,DATE(2026,8,1))+1))/30.4 -> 0.098684211 | Y13: =$H13*MAX(0,(MIN($G13,DATE(2026,9,30))-MAX($E13,DATE(2026,9,1))+1))/30.4 -> 0 | Z13: =$H13*MAX(0,(MIN($G13,DATE(2026,10,31))-MAX($E13,DATE(2026,10,1))+1))/30.4 -> 0 | AA13: =$H13*MAX(0,(MIN($G13,DATE(2026,11,30))-MAX($E13,DATE(2026,11,1))+1))/30.4 -> 0 | AB13: =$H13*MAX(0,(MIN($G13,DATE(2026,12,31))-MAX($E13,DATE(2026,12,1))+1))/30.4 -> 0
A14: 3 | B14: 4 | C14: FD | D14: AP/P | E14: 46209 | F14: 5 | G14: 46244 | H14: 0.375 | I14: Not Resourced | J14: =IFERROR(VLOOKUP(D14,Role_Mapping!$A$5:$D$31,2,FALSE()),"UNMAPPED") -> Associate Partner | K14: =IFERROR(VLOOKUP(D14,Role_Mapping!$A$5:$D$31,3,FALSE()),"IN") -> UK | L14: =IFERROR(SUMPRODUCT((Rate_Card!$A$5:$A$34=J14)*(Rate_Card!$B$5:$B$34=K14)*Rate_Card!$C$5:$C$34),0) -> 3526 | M14: =F14*5 -> 25 | N14: =L14*M14*H14 -> 33056.25 | O14: =(G14-E14)+1 -> 36 | P14: =IFERROR(VLOOKUP(D14,Role_Mapping!$A$5:$D$31,4,FALSE()),"UNMAPPED") -> GTM | Q14: =$N14*MAX(0,(MIN($G14,DATE(2026,7,31))-MAX($E14,DATE(2026,7,1))+1))/$O14 -> 23873.958 | R14: =$N14*MAX(0,(MIN($G14,DATE(2026,8,31))-MAX($E14,DATE(2026,8,1))+1))/$O14 -> 9182.2917 | S14: =$N14*MAX(0,(MIN($G14,DATE(2026,9,30))-MAX($E14,DATE(2026,9,1))+1))/$O14 -> 0 | T14: =$N14*MAX(0,(MIN($G14,DATE(2026,10,31))-MAX($E14,DATE(2026,10,1))+1))/$O14 -> 0 | U14: =$N14*MAX(0,(MIN($G14,DATE(2026,11,30))-MAX($E14,DATE(2026,11,1))+1))/$O14 -> 0 | V14: =$N14*MAX(0,(MIN($G14,DATE(2026,12,31))-MAX($E14,DATE(2026,12,1))+1))/$O14 -> 0 | W14: =$H14*MAX(0,(MIN($G14,DATE(2026,7,31))-MAX($E14,DATE(2026,7,1))+1))/30.4 -> 0.32072368 | X14: =$H14*MAX(0,(MIN($G14,DATE(2026,8,31))-MAX($E14,DATE(2026,8,1))+1))/30.4 -> 0.12335526 | Y14: =$H14*MAX(0,(MIN($G14,DATE(2026,9,30))-MAX($E14,DATE(2026,9,1))+1))/30.4 -> 0 | Z14: =$H14*MAX(0,(MIN($G14,DATE(2026,10,31))-MAX($E14,DATE(2026,10,1))+1))/30.4 -> 0 | AA14: =$H14*MAX(0,(MIN($G14,DATE(2026,11,30))-MAX($E14,DATE(2026,11,1))+1))/30.4 -> 0 | AB14: =$H14*MAX(0,(MIN($G14,DATE(2026,12,31))-MAX($E14,DATE(2026,12,1))+1))/30.4 -> 0
A15: 3 | B15: 4 | C15: FD | D15: PA | E15: 46209 | F15: 5 | G15: 46244 | H15: 0.25 | I15: Not Resourced | J15: =IFERROR(VLOOKUP(D15,Role_Mapping!$A$5:$D$31,2,FALSE()),"UNMAPPED") -> Principal Technology Architect | K15: =IFERROR(VLOOKUP(D15,Role_Mapping!$A$5:$D$31,3,FALSE()),"IN") -> IN | L15: =IFERROR(SUMPRODUCT((Rate_Card!$A$5:$A$34=J15)*(Rate_Card!$B$5:$B$34=K15)*Rate_Card!$C$5:$C$34),0) -> 845 | M15: =F15*5 -> 25 | N15: =L15*M15*H15 -> 5281.25 | O15: =(G15-E15)+1 -> 36 | P15: =IFERROR(VLOOKUP(D15,Role_Mapping!$A$5:$D$31,4,FALSE()),"UNMAPPED") -> Full Stack | Q15: =$N15*MAX(0,(MIN($G15,DATE(2026,7,31))-MAX($E15,DATE(2026,7,1))+1))/$O15 -> 3814.2361 | R15: =$N15*MAX(0,(MIN($G15,DATE(2026,8,31))-MAX($E15,DATE(2026,8,1))+1))/$O15 -> 1467.0139 | S15: =$N15*MAX(0,(MIN($G15,DATE(2026,9,30))-MAX($E15,DATE(2026,9,1))+1))/$O15 -> 0 | T15: =$N15*MAX(0,(MIN($G15,DATE(2026,10,31))-MAX($E15,DATE(2026,10,1))+1))/$O15 -> 0 | U15: =$N15*MAX(0,(MIN($G15,DATE(2026,11,30))-MAX($E15,DATE(2026,11,1))+1))/$O15 -> 0 | V15: =$N15*MAX(0,(MIN($G15,DATE(2026,12,31))-MAX($E15,DATE(2026,12,1))+1))/$O15 -> 0 | W15: =$H15*MAX(0,(MIN($G15,DATE(2026,7,31))-MAX($E15,DATE(2026,7,1))+1))/30.4 -> 0.21381579 | X15: =$H15*MAX(0,(MIN($G15,DATE(2026,8,31))-MAX($E15,DATE(2026,8,1))+1))/30.4 -> 0.082236842 | Y15: =$H15*MAX(0,(MIN($G15,DATE(2026,9,30))-MAX($E15,DATE(2026,9,1))+1))/30.4 -> 0 | Z15: =$H15*MAX(0,(MIN($G15,DATE(2026,10,31))-MAX($E15,DATE(2026,10,1))+1))/30.4 -> 0 | AA15: =$H15*MAX(0,(MIN($G15,DATE(2026,11,30))-MAX($E15,DATE(2026,11,1))+1))/30.4 -> 0 | AB15: =$H15*MAX(0,(MIN($G15,DATE(2026,12,31))-MAX($E15,DATE(2026,12,1))+1))/30.4 -> 0
A16: 3 | B16: 4 | C16: FD | D16: SC (EM) | E16: 46209 | F16: 5 | G16: 46244 | H16: 0.5 | I16: Not Resourced | J16: =IFERROR(VLOOKUP(D16,Role_Mapping!$A$5:$D$31,2,FALSE()),"UNMAPPED") -> Senior Consultant | K16: =IFERROR(VLOOKUP(D16,Role_Mapping!$A$5:$D$31,3,FALSE()),"IN") -> UK | L16: =IFERROR(SUMPRODUCT((Rate_Card!$A$5:$A$34=J16)*(Rate_Card!$B$5:$B$34=K16)*Rate_Card!$C$5:$C$34),0) -> 2798 | M16: =F16*5 -> 25 | N16: =L16*M16*H16 -> 34975 | O16: =(G16-E16)+1 -> 36 | P16: =IFERROR(VLOOKUP(D16,Role_Mapping!$A$5:$D$31,4,FALSE()),"UNMAPPED") -> Consulting | Q16: =$N16*MAX(0,(MIN($G16,DATE(2026,7,31))-MAX($E16,DATE(2026,7,1))+1))/$O16 -> 25259.722 | R16: =$N16*MAX(0,(MIN($G16,DATE(2026,8,31))-MAX($E16,DATE(2026,8,1))+1))/$O16 -> 9715.2778 | S16: =$N16*MAX(0,(MIN($G16,DATE(2026,9,30))-MAX($E16,DATE(2026,9,1))+1))/$O16 -> 0 | T16: =$N16*MAX(0,(MIN($G16,DATE(2026,10,31))-MAX($E16,DATE(2026,10,1))+1))/$O16 -> 0 | U16: =$N16*MAX(0,(MIN($G16,DATE(2026,11,30))-MAX($E16,DATE(2026,11,1))+1))/$O16 -> 0 | V16: =$N16*MAX(0,(MIN($G16,DATE(2026,12,31))-MAX($E16,DATE(2026,12,1))+1))/$O16 -> 0 | W16: =$H16*MAX(0,(MIN($G16,DATE(2026,7,31))-MAX($E16,DATE(2026,7,1))+1))/30.4 -> 0.42763158 | X16: =$H16*MAX(0,(MIN($G16,DATE(2026,8,31))-MAX($E16,DATE(2026,8,1))+1))/30.4 -> 0.16447368 | Y16: =$H16*MAX(0,(MIN($G16,DATE(2026,9,30))-MAX($E16,DATE(2026,9,1))+1))/30.4 -> 0 | Z16: =$H16*MAX(0,(MIN($G16,DATE(2026,10,31))-MAX($E16,DATE(2026,10,1))+1))/30.4 -> 0 | AA16: =$H16*MAX(0,(MIN($G16,DATE(2026,11,30))-MAX($E16,DATE(2026,11,1))+1))/30.4 -> 0 | AB16: =$H16*MAX(0,(MIN($G16,DATE(2026,12,31))-MAX($E16,DATE(2026,12,1))+1))/30.4 -> 0
... A61: 11 | B61: 5 | C61: Kawasaki | D61: P | E61: 46195 | F61: 8 | G61: 46251 | H61: 0.125 | I61: Resourced | J61: =IFERROR(VLOOKUP(D61,Role_Mapping!$A$5:$D$31,2,FALSE()),"UNMAPPED") -> Associate Partner | K61: =IFERROR(VLOOKUP(D61,Role_Mapping!$A$5:$D$31,3,FALSE()),"IN") -> UK | L61: =IFERROR(SUMPRODUCT((Rate_Card!$A$5:$A$34=J61)*(Rate_Card!$B$5:$B$34=K61)*Rate_Card!$C$5:$C$34),0) -> 3526 | M61: =F61*5 -> 40 | N61: =L61*M61*H61 -> 17630 | O61: =(G61-E61)+1 -> 57 | P61: =IFERROR(VLOOKUP(D61,Role_Mapping!$A$5:$D$31,4,FALSE()),"UNMAPPED") -> GTM | Q61: =$N61*MAX(0,(MIN($G61,DATE(2026,7,31))-MAX($E61,DATE(2026,7,1))+1))/$O61 -> 9588.2456 | R61: =$N61*MAX(0,(MIN($G61,DATE(2026,8,31))-MAX($E61,DATE(2026,8,1))+1))/$O61 -> 5258.0702 | S61: =$N61*MAX(0,(MIN($G61,DATE(2026,9,30))-MAX($E61,DATE(2026,9,1))+1))/$O61 -> 0 | T61: =$N61*MAX(0,(MIN($G61,DATE(2026,10,31))-MAX($E61,DATE(2026,10,1))+1))/$O61 -> 0 | U61: =$N61*MAX(0,(MIN($G61,DATE(2026,11,30))-MAX($E61,DATE(2026,11,1))+1))/$O61 -> 0 | V61: =$N61*MAX(0,(MIN($G61,DATE(2026,12,31))-MAX($E61,DATE(2026,12,1))+1))/$O61 -> 0 | W61: =$H61*MAX(0,(MIN($G61,DATE(2026,7,31))-MAX($E61,DATE(2026,7,1))+1))/30.4 -> 0.12746711 | X61: =$H61*MAX(0,(MIN($G61,DATE(2026,8,31))-MAX($E61,DATE(2026,8,1))+1))/30.4 -> 0.069901316 | Y61: =$H61*MAX(0,(MIN($G61,DATE(2026,9,30))-MAX($E61,DATE(2026,9,1))+1))/30.4 -> 0 | Z61: =$H61*MAX(0,(MIN($G61,DATE(2026,10,31))-MAX($E61,DATE(2026,10,1))+1))/30.4 -> 0 | AA61: =$H61*MAX(0,(MIN($G61,DATE(2026,11,30))-MAX($E61,DATE(2026,11,1))+1))/30.4 -> 0 | AB61: =$H61*MAX(0,(MIN($G61,DATE(2026,12,31))-MAX($E61,DATE(2026,12,1))+1))/30.4 -> 0
A62: 12 | B62: 5 | D62: PA | E62: 46195 | F62: 5 | G62: 46230 | H62: 0.125 | I62: Resourced | J62: =IFERROR(VLOOKUP(D62,Role_Mapping!$A$5:$D$31,2,FALSE()),"UNMAPPED") -> Principal Technology Architect | K62: =IFERROR(VLOOKUP(D62,Role_Mapping!$A$5:$D$31,3,FALSE()),"IN") -> IN | L62: =IFERROR(SUMPRODUCT((Rate_Card!$A$5:$A$34=J62)*(Rate_Card!$B$5:$B$34=K62)*Rate_Card!$C$5:$C$34),0) -> 845 | M62: =F62*5 -> 25 | N62: =L62*M62*H62 -> 2640.625 | O62: =(G62-E62)+1 -> 36 | P62: =IFERROR(VLOOKUP(D62,Role_Mapping!$A$5:$D$31,4,FALSE()),"UNMAPPED") -> Full Stack | Q62: =$N62*MAX(0,(MIN($G62,DATE(2026,7,31))-MAX($E62,DATE(2026,7,1))+1))/$O62 -> 1980.4688 | R62: =$N62*MAX(0,(MIN($G62,DATE(2026,8,31))-MAX($E62,DATE(2026,8,1))+1))/$O62 -> 0 | S62: =$N62*MAX(0,(MIN($G62,DATE(2026,9,30))-MAX($E62,DATE(2026,9,1))+1))/$O62 -> 0 | T62: =$N62*MAX(0,(MIN($G62,DATE(2026,10,31))-MAX($E62,DATE(2026,10,1))+1))/$O62 -> 0 | U62: =$N62*MAX(0,(MIN($G62,DATE(2026,11,30))-MAX($E62,DATE(2026,11,1))+1))/$O62 -> 0 | V62: =$N62*MAX(0,(MIN($G62,DATE(2026,12,31))-MAX($E62,DATE(2026,12,1))+1))/$O62 -> 0 | W62: =$H62*MAX(0,(MIN($G62,DATE(2026,7,31))-MAX($E62,DATE(2026,7,1))+1))/30.4 -> 0.11101974 | X62: =$H62*MAX(0,(MIN($G62,DATE(2026,8,31))-MAX($E62,DATE(2026,8,1))+1))/30.4 -> 0 | Y62: =$H62*MAX(0,(MIN($G62,DATE(2026,9,30))-MAX($E62,DATE(2026,9,1))+1))/30.4 -> 0 | Z62: =$H62*MAX(0,(MIN($G62,DATE(2026,10,31))-MAX($E62,DATE(2026,10,1))+1))/30.4 -> 0 | AA62: =$H62*MAX(0,(MIN($G62,DATE(2026,11,30))-MAX($E62,DATE(2026,11,1))+1))/30.4 -> 0 | AB62: =$H62*MAX(0,(MIN($G62,DATE(2026,12,31))-MAX($E62,DATE(2026,12,1))+1))/30.4 -> 0
A63: 13 | B63: 5 | D63: SC | E63: 46195 | F63: 5 | G63: 46230 | H63: 0.5 | I63: Not Resourced | J63: =IFERROR(VLOOKUP(D63,Role_Mapping!$A$5:$D$31,2,FALSE()),"UNMAPPED") -> Senior Consultant | K63: =IFERROR(VLOOKUP(D63,Role_Mapping!$A$5:$D$31,3,FALSE()),"IN") -> UK | L63: =IFERROR(SUMPRODUCT((Rate_Card!$A$5:$A$34=J63)*(Rate_Card!$B$5:$B$34=K63)*Rate_Card!$C$5:$C$34),0) -> 2798 | M63: =F63*5 -> 25 | N63: =L63*M63*H63 -> 34975 | O63: =(G63-E63)+1 -> 36 | P63: =IFERROR(VLOOKUP(D63,Role_Mapping!$A$5:$D$31,4,FALSE()),"UNMAPPED") -> Consulting | Q63: =$N63*MAX(0,(MIN($G63,DATE(2026,7,31))-MAX($E63,DATE(2026,7,1))+1))/$O63 -> 26231.25 | R63: =$N63*MAX(0,(MIN($G63,DATE(2026,8,31))-MAX($E63,DATE(2026,8,1))+1))/$O63 -> 0 | S63: =$N63*MAX(0,(MIN($G63,DATE(2026,9,30))-MAX($E63,DATE(2026,9,1))+1))/$O63 -> 0 | T63: =$N63*MAX(0,(MIN($G63,DATE(2026,10,31))-MAX($E63,DATE(2026,10,1))+1))/$O63 -> 0 | U63: =$N63*MAX(0,(MIN($G63,DATE(2026,11,30))-MAX($E63,DATE(2026,11,1))+1))/$O63 -> 0 | V63: =$N63*MAX(0,(MIN($G63,DATE(2026,12,31))-MAX($E63,DATE(2026,12,1))+1))/$O63 -> 0 | W63: =$H63*MAX(0,(MIN($G63,DATE(2026,7,31))-MAX($E63,DATE(2026,7,1))+1))/30.4 -> 0.44407895 | X63: =$H63*MAX(0,(MIN($G63,DATE(2026,8,31))-MAX($E63,DATE(2026,8,1))+1))/30.4 -> 0 | Y63: =$H63*MAX(0,(MIN($G63,DATE(2026,9,30))-MAX($E63,DATE(2026,9,1))+1))/30.4 -> 0 | Z63: =$H63*MAX(0,(MIN($G63,DATE(2026,10,31))-MAX($E63,DATE(2026,10,1))+1))/30.4 -> 0 | AA63: =$H63*MAX(0,(MIN($G63,DATE(2026,11,30))-MAX($E63,DATE(2026,11,1))+1))/30.4 -> 0 | AB63: =$H63*MAX(0,(MIN($G63,DATE(2026,12,31))-MAX($E63,DATE(2026,12,1))+1))/30.4 -> 0
A64: 14 | B64: 5 | D64: SAC | E64: 46195 | F64: 5 | G64: 46230 | H64: 1 | I64: Not Resourced | J64: =IFERROR(VLOOKUP(D64,Role_Mapping!$A$5:$D$31,2,FALSE()),"UNMAPPED") -> Senior Associate Consultant | K64: =IFERROR(VLOOKUP(D64,Role_Mapping!$A$5:$D$31,3,FALSE()),"IN") -> IN | L64: =IFERROR(SUMPRODUCT((Rate_Card!$A$5:$A$34=J64)*(Rate_Card!$B$5:$B$34=K64)*Rate_Card!$C$5:$C$34),0) -> 683 | M64: =F64*5 -> 25 | N64: =L64*M64*H64 -> 17075 | O64: =(G64-E64)+1 -> 36 | P64: =IFERROR(VLOOKUP(D64,Role_Mapping!$A$5:$D$31,4,FALSE()),"UNMAPPED") -> Consulting | Q64: =$N64*MAX(0,(MIN($G64,DATE(2026,7,31))-MAX($E64,DATE(2026,7,1))+1))/$O64 -> 12806.25 | R64: =$N64*MAX(0,(MIN($G64,DATE(2026,8,31))-MAX($E64,DATE(2026,8,1))+1))/$O64 -> 0 | S64: =$N64*MAX(0,(MIN($G64,DATE(2026,9,30))-MAX($E64,DATE(2026,9,1))+1))/$O64 -> 0 | T64: =$N64*MAX(0,(MIN($G64,DATE(2026,10,31))-MAX($E64,DATE(2026,10,1))+1))/$O64 -> 0 | U64: =$N64*MAX(0,(MIN($G64,DATE(2026,11,30))-MAX($E64,DATE(2026,11,1))+1))/$O64 -> 0 | V64: =$N64*MAX(0,(MIN($G64,DATE(2026,12,31))-MAX($E64,DATE(2026,12,1))+1))/$O64 -> 0 | W64: =$H64*MAX(0,(MIN($G64,DATE(2026,7,31))-MAX($E64,DATE(2026,7,1))+1))/30.4 -> 0.88815789 | X64: =$H64*MAX(0,(MIN($G64,DATE(2026,8,31))-MAX($E64,DATE(2026,8,1))+1))/30.4 -> 0 | Y64: =$H64*MAX(0,(MIN($G64,DATE(2026,9,30))-MAX($E64,DATE(2026,9,1))+1))/30.4 -> 0 | Z64: =$H64*MAX(0,(MIN($G64,DATE(2026,10,31))-MAX($E64,DATE(2026,10,1))+1))/30.4 -> 0 | AA64: =$H64*MAX(0,(MIN($G64,DATE(2026,11,30))-MAX($E64,DATE(2026,11,1))+1))/30.4 -> 0 | AB64: =$H64*MAX(0,(MIN($G64,DATE(2026,12,31))-MAX($E64,DATE(2026,12,1))+1))/30.4 -> 0
A65: 15 | B65: 5 | D65: Enabler | E65: 46202 | F65: 5 | G65: 46237 | H65: 1 | I65: Not Resourced | J65: =IFERROR(VLOOKUP(D65,Role_Mapping!$A$5:$D$31,2,FALSE()),"UNMAPPED") -> Solutions Enabler | K65: =IFERROR(VLOOKUP(D65,Role_Mapping!$A$5:$D$31,3,FALSE()),"IN") -> IN | L65: =IFERROR(SUMPRODUCT((Rate_Card!$A$5:$A$34=J65)*(Rate_Card!$B$5:$B$34=K65)*Rate_Card!$C$5:$C$34),0) -> 683 | M65: =F65*5 -> 25 | N65: =L65*M65*H65 -> 17075 | O65: =(G65-E65)+1 -> 36 | P65: =IFERROR(VLOOKUP(D65,Role_Mapping!$A$5:$D$31,4,FALSE()),"UNMAPPED") -> Data Engineering | Q65: =$N65*MAX(0,(MIN($G65,DATE(2026,7,31))-MAX($E65,DATE(2026,7,1))+1))/$O65 -> 14703.472 | R65: =$N65*MAX(0,(MIN($G65,DATE(2026,8,31))-MAX($E65,DATE(2026,8,1))+1))/$O65 -> 1422.9167 | S65: =$N65*MAX(0,(MIN($G65,DATE(2026,9,30))-MAX($E65,DATE(2026,9,1))+1))/$O65 -> 0 | T65: =$N65*MAX(0,(MIN($G65,DATE(2026,10,31))-MAX($E65,DATE(2026,10,1))+1))/$O65 -> 0 | U65: =$N65*MAX(0,(MIN($G65,DATE(2026,11,30))-MAX($E65,DATE(2026,11,1))+1))/$O65 -> 0 | V65: =$N65*MAX(0,(MIN($G65,DATE(2026,12,31))-MAX($E65,DATE(2026,12,1))+1))/$O65 -> 0 | W65: =$H65*MAX(0,(MIN($G65,DATE(2026,7,31))-MAX($E65,DATE(2026,7,1))+1))/30.4 -> 1.0197368 | X65: =$H65*MAX(0,(MIN($G65,DATE(2026,8,31))-MAX($E65,DATE(2026,8,1))+1))/30.4 -> 0.098684211 | Y65: =$H65*MAX(0,(MIN($G65,DATE(2026,9,30))-MAX($E65,DATE(2026,9,1))+1))/30.4 -> 0 | Z65: =$H65*MAX(0,(MIN($G65,DATE(2026,10,31))-MAX($E65,DATE(2026,10,1))+1))/30.4 -> 0 | AA65: =$H65*MAX(0,(MIN($G65,DATE(2026,11,30))-MAX($E65,DATE(2026,11,1))+1))/30.4 -> 0 | AB65: =$H65*MAX(0,(MIN($G65,DATE(2026,12,31))-MAX($E65,DATE(2026,12,1))+1))/30.4 -> 0
A66: 16 | B66: 5 | D66: SSE | E66: 46202 | F66: 5 | G66: 46237 | H66: 1 | I66: Not Resourced | J66: =IFERROR(VLOOKUP(D66,Role_Mapping!$A$5:$D$31,2,FALSE()),"UNMAPPED") -> Senior Software Engineer | K66: =IFERROR(VLOOKUP(D66,Role_Mapping!$A$5:$D$31,3,FALSE()),"IN") -> IN | L66: =IFERROR(SUMPRODUCT((Rate_Card!$A$5:$A$34=J66)*(Rate_Card!$B$5:$B$34=K66)*Rate_Card!$C$5:$C$34),0) -> 585 | M66: =F66*5 -> 25 | N66: =L66*M66*H66 -> 14625 | O66: =(G66-E66)+1 -> 36 | P66: =IFERROR(VLOOKUP(D66,Role_Mapping!$A$5:$D$31,4,FALSE()),"UNMAPPED") -> Full Stack | Q66: =$N66*MAX(0,(MIN($G66,DATE(2026,7,31))-MAX($E66,DATE(2026,7,1))+1))/$O66 -> 12593.75 | R66: =$N66*MAX(0,(MIN($G66,DATE(2026,8,31))-MAX($E66,DATE(2026,8,1))+1))/$O66 -> 1218.75 | S66: =$N66*MAX(0,(MIN($G66,DATE(2026,9,30))-MAX($E66,DATE(2026,9,1))+1))/$O66 -> 0 | T66: =$N66*MAX(0,(MIN($G66,DATE(2026,10,31))-MAX($E66,DATE(2026,10,1))+1))/$O66 -> 0 | U66: =$N66*MAX(0,(MIN($G66,DATE(2026,11,30))-MAX($E66,DATE(2026,11,1))+1))/$O66 -> 0 | V66: =$N66*MAX(0,(MIN($G66,DATE(2026,12,31))-MAX($E66,DATE(2026,12,1))+1))/$O66 -> 0 | W66: =$H66*MAX(0,(MIN($G66,DATE(2026,7,31))-MAX($E66,DATE(2026,7,1))+1))/30.4 -> 1.0197368 | X66: =$H66*MAX(0,(MIN($G66,DATE(2026,8,31))-MAX($E66,DATE(2026,8,1))+1))/30.4 -> 0.098684211 | Y66: =$H66*MAX(0,(MIN($G66,DATE(2026,9,30))-MAX($E66,DATE(2026,9,1))+1))/30.4 -> 0 | Z66: =$H66*MAX(0,(MIN($G66,DATE(2026,10,31))-MAX($E66,DATE(2026,10,1))+1))/30.4 -> 0 | AA66: =$H66*MAX(0,(MIN($G66,DATE(2026,11,30))-MAX($E66,DATE(2026,11,1))+1))/30.4 -> 0 | AB66: =$H66*MAX(0,(MIN($G66,DATE(2026,12,31))-MAX($E66,DATE(2026,12,1))+1))/30.4 -> 0
A67: 17 | B67: 5 | D67: SE | E67: 46202 | F67: 5 | G67: 46237 | H67: 1 | I67: Not Resourced | J67: =IFERROR(VLOOKUP(D67,Role_Mapping!$A$5:$D$31,2,FALSE()),"UNMAPPED") -> Software Engineer | K67: =IFERROR(VLOOKUP(D67,Role_Mapping!$A$5:$D$31,3,FALSE()),"IN") -> IN | L67: =IFERROR(SUMPRODUCT((Rate_Card!$A$5:$A$34=J67)*(Rate_Card!$B$5:$B$34=K67)*Rate_Card!$C$5:$C$34),0) -> 455 | M67: =F67*5 -> 25 | N67: =L67*M67*H67 -> 11375 | O67: =(G67-E67)+1 -> 36 | P67: =IFERROR(VLOOKUP(D67,Role_Mapping!$A$5:$D$31,4,FALSE()),"UNMAPPED") -> Full Stack | Q67: =$N67*MAX(0,(MIN($G67,DATE(2026,7,31))-MAX($E67,DATE(2026,7,1))+1))/$O67 -> 9795.1389 | R67: =$N67*MAX(0,(MIN($G67,DATE(2026,8,31))-MAX($E67,DATE(2026,8,1))+1))/$O67 -> 947.91667 | S67: =$N67*MAX(0,(MIN($G67,DATE(2026,9,30))-MAX($E67,DATE(2026,9,1))+1))/$O67 -> 0 | T67: =$N67*MAX(0,(MIN($G67,DATE(2026,10,31))-MAX($E67,DATE(2026,10,1))+1))/$O67 -> 0 | U67: =$N67*MAX(0,(MIN($G67,DATE(2026,11,30))-MAX($E67,DATE(2026,11,1))+1))/$O67 -> 0 | V67: =$N67*MAX(0,(MIN($G67,DATE(2026,12,31))-MAX($E67,DATE(2026,12,1))+1))/$O67 -> 0 | W67: =$H67*MAX(0,(MIN($G67,DATE(2026,7,31))-MAX($E67,DATE(2026,7,1))+1))/30.4 -> 1.0197368 | X67: =$H67*MAX(0,(MIN($G67,DATE(2026,8,31))-MAX($E67,DATE(2026,8,1))+1))/30.4 -> 0.098684211 | Y67: =$H67*MAX(0,(MIN($G67,DATE(2026,9,30))-MAX($E67,DATE(2026,9,1))+1))/30.4 -> 0 | Z67: =$H67*MAX(0,(MIN($G67,DATE(2026,10,31))-MAX($E67,DATE(2026,10,1))+1))/30.4 -> 0 | AA67: =$H67*MAX(0,(MIN($G67,DATE(2026,11,30))-MAX($E67,DATE(2026,11,1))+1))/30.4 -> 0 | AB67: =$H67*MAX(0,(MIN($G67,DATE(2026,12,31))-MAX($E67,DATE(2026,12,1))+1))/30.4 -> 0
A68: 18 | B68: 2 | C68: Honda | D68: SSE | E68: 46202 | F68: 5 | G68: 46237 | H68: 1 | I68: Not Resourced | J68: =IFERROR(VLOOKUP(D68,Role_Mapping!$A$5:$D$31,2,FALSE()),"UNMAPPED") -> Senior Software Engineer | K68: =IFERROR(VLOOKUP(D68,Role_Mapping!$A$5:$D$31,3,FALSE()),"IN") -> IN | L68: =IFERROR(SUMPRODUCT((Rate_Card!$A$5:$A$34=J68)*(Rate_Card!$B$5:$B$34=K68)*Rate_Card!$C$5:$C$34),0) -> 585 | M68: =F68*5 -> 25 | N68: =L68*M68*H68 -> 14625 | O68: =(G68-E68)+1 -> 36 | P68: =IFERROR(VLOOKUP(D68,Role_Mapping!$A$5:$D$31,4,FALSE()),"UNMAPPED") -> Full Stack | Q68: =$N68*MAX(0,(MIN($G68,DATE(2026,7,31))-MAX($E68,DATE(2026,7,1))+1))/$O68 -> 12593.75 | R68: =$N68*MAX(0,(MIN($G68,DATE(2026,8,31))-MAX($E68,DATE(2026,8,1))+1))/$O68 -> 1218.75 | S68: =$N68*MAX(0,(MIN($G68,DATE(2026,9,30))-MAX($E68,DATE(2026,9,1))+1))/$O68 -> 0 | T68: =$N68*MAX(0,(MIN($G68,DATE(2026,10,31))-MAX($E68,DATE(2026,10,1))+1))/$O68 -> 0 | U68: =$N68*MAX(0,(MIN($G68,DATE(2026,11,30))-MAX($E68,DATE(2026,11,1))+1))/$O68 -> 0 | V68: =$N68*MAX(0,(MIN($G68,DATE(2026,12,31))-MAX($E68,DATE(2026,12,1))+1))/$O68 -> 0 | W68: =$H68*MAX(0,(MIN($G68,DATE(2026,7,31))-MAX($E68,DATE(2026,7,1))+1))/30.4 -> 1.0197368 | X68: =$H68*MAX(0,(MIN($G68,DATE(2026,8,31))-MAX($E68,DATE(2026,8,1))+1))/30.4 -> 0.098684211 | Y68: =$H68*MAX(0,(MIN($G68,DATE(2026,9,30))-MAX($E68,DATE(2026,9,1))+1))/30.4 -> 0 | Z68: =$H68*MAX(0,(MIN($G68,DATE(2026,10,31))-MAX($E68,DATE(2026,10,1))+1))/30.4 -> 0 | AA68: =$H68*MAX(0,(MIN($G68,DATE(2026,11,30))-MAX($E68,DATE(2026,11,1))+1))/30.4 -> 0 | AB68: =$H68*MAX(0,(MIN($G68,DATE(2026,12,31))-MAX($E68,DATE(2026,12,1))+1))/30.4 -> 0
A69: 19 | B69: 5 | C69: KTM | D69: P | E69: 46195 | F69: 12 | G69: 46279 | H69: 0.5 | I69: Part Resourced | J69: =IFERROR(VLOOKUP(D69,Role_Mapping!$A$5:$D$31,2,FALSE()),"UNMAPPED") -> Associate Partner | K69: =IFERROR(VLOOKUP(D69,Role_Mapping!$A$5:$D$31,3,FALSE()),"IN") -> UK | L69: =IFERROR(SUMPRODUCT((Rate_Card!$A$5:$A$34=J69)*(Rate_Card!$B$5:$B$34=K69)*Rate_Card!$C$5:$C$34),0) -> 3526 | M69: =F69*5 -> 60 | N69: =L69*M69*H69 -> 105780 | O69: =(G69-E69)+1 -> 85 | P69: =IFERROR(VLOOKUP(D69,Role_Mapping!$A$5:$D$31,4,FALSE()),"UNMAPPED") -> GTM | Q69: =$N69*MAX(0,(MIN($G69,DATE(2026,7,31))-MAX($E69,DATE(2026,7,1))+1))/$O69 -> 38578.588 | R69: =$N69*MAX(0,(MIN($G69,DATE(2026,8,31))-MAX($E69,DATE(2026,8,1))+1))/$O69 -> 38578.588 | S69: =$N69*MAX(0,(MIN($G69,DATE(2026,9,30))-MAX($E69,DATE(2026,9,1))+1))/$O69 -> 17422.588 | T69: =$N69*MAX(0,(MIN($G69,DATE(2026,10,31))-MAX($E69,DATE(2026,10,1))+1))/$O69 -> 0 | U69: =$N69*MAX(0,(MIN($G69,DATE(2026,11,30))-MAX($E69,DATE(2026,11,1))+1))/$O69 -> 0 | V69: =$N69*MAX(0,(MIN($G69,DATE(2026,12,31))-MAX($E69,DATE(2026,12,1))+1))/$O69 -> 0 | W69: =$H69*MAX(0,(MIN($G69,DATE(2026,7,31))-MAX($E69,DATE(2026,7,1))+1))/30.4 -> 0.50986842 | X69: =$H69*MAX(0,(MIN($G69,DATE(2026,8,31))-MAX($E69,DATE(2026,8,1))+1))/30.4 -> 0.50986842 | Y69: =$H69*MAX(0,(MIN($G69,DATE(2026,9,30))-MAX($E69,DATE(2026,9,1))+1))/30.4 -> 0.23026316 | Z69: =$H69*MAX(0,(MIN($G69,DATE(2026,10,31))-MAX($E69,DATE(2026,10,1))+1))/30.4 -> 0 | AA69: =$H69*MAX(0,(MIN($G69,DATE(2026,11,30))-MAX($E69,DATE(2026,11,1))+1))/30.4 -> 0 | AB69: =$H69*MAX(0,(MIN($G69,DATE(2026,12,31))-MAX($E69,DATE(2026,12,1))+1))/30.4 -> 0
A70: 20 | B70: 5 | D70: C | E70: 46195 | F70: 5 | G70: 46230 | H70: 0.5 | I70: Not Resourced | J70: =IFERROR(VLOOKUP(D70,Role_Mapping!$A$5:$D$31,2,FALSE()),"UNMAPPED") -> Consultant | K70: =IFERROR(VLOOKUP(D70,Role_Mapping!$A$5:$D$31,3,FALSE()),"IN") -> IN | L70: =IFERROR(SUMPRODUCT((Rate_Card!$A$5:$A$34=J70)*(Rate_Card!$B$5:$B$34=K70)*Rate_Card!$C$5:$C$34),0) -> 683 | M70: =F70*5 -> 25 | N70: =L70*M70*H70 -> 8537.5 | O70: =(G70-E70)+1 -> 36 | P70: =IFERROR(VLOOKUP(D70,Role_Mapping!$A$5:$D$31,4,FALSE()),"UNMAPPED") -> Consulting | Q70: =$N70*MAX(0,(MIN($G70,DATE(2026,7,31))-MAX($E70,DATE(2026,7,1))+1))/$O70 -> 6403.125 | R70: =$N70*MAX(0,(MIN($G70,DATE(2026,8,31))-MAX($E70,DATE(2026,8,1))+1))/$O70 -> 0 | S70: =$N70*MAX(0,(MIN($G70,DATE(2026,9,30))-MAX($E70,DATE(2026,9,1))+1))/$O70 -> 0 | T70: =$N70*MAX(0,(MIN($G70,DATE(2026,10,31))-MAX($E70,DATE(2026,10,1))+1))/$O70 -> 0 | U70: =$N70*MAX(0,(MIN($G70,DATE(2026,11,30))-MAX($E70,DATE(2026,11,1))+1))/$O70 -> 0 | V70: =$N70*MAX(0,(MIN($G70,DATE(2026,12,31))-MAX($E70,DATE(2026,12,1))+1))/$O70 -> 0 | W70: =$H70*MAX(0,(MIN($G70,DATE(2026,7,31))-MAX($E70,DATE(2026,7,1))+1))/30.4 -> 0.44407895 | X70: =$H70*MAX(0,(MIN($G70,DATE(2026,8,31))-MAX($E70,DATE(2026,8,1))+1))/30.4 -> 0 | Y70: =$H70*MAX(0,(MIN($G70,DATE(2026,9,30))-MAX($E70,DATE(2026,9,1))+1))/30.4 -> 0 | Z70: =$H70*MAX(0,(MIN($G70,DATE(2026,10,31))-MAX($E70,DATE(2026,10,1))+1))/30.4 -> 0 | AA70: =$H70*MAX(0,(MIN($G70,DATE(2026,11,30))-MAX($E70,DATE(2026,11,1))+1))/30.4 -> 0 | AB70: =$H70*MAX(0,(MIN($G70,DATE(2026,12,31))-MAX($E70,DATE(2026,12,1))+1))/30.4 -> 0
A71: 21 | B71: 5 | D71: PA | E71: 46195 | F71: 5 | G71: 46230 | H71: 0.25 | I71: Not Resourced | J71: =IFERROR(VLOOKUP(D71,Role_Mapping!$A$5:$D$31,2,FALSE()),"UNMAPPED") -> Principal Technology Architect | K71: =IFERROR(VLOOKUP(D71,Role_Mapping!$A$5:$D$31,3,FALSE()),"IN") -> IN | L71: =IFERROR(SUMPRODUCT((Rate_Card!$A$5:$A$34=J71)*(Rate_Card!$B$5:$B$34=K71)*Rate_Card!$C$5:$C$34),0) -> 845 | M71: =F71*5 -> 25 | N71: =L71*M71*H71 -> 5281.25 | O71: =(G71-E71)+1 -> 36 | P71: =IFERROR(VLOOKUP(D71,Role_Mapping!$A$5:$D$31,4,FALSE()),"UNMAPPED") -> Full Stack | Q71: =$N71*MAX(0,(MIN($G71,DATE(2026,7,31))-MAX($E71,DATE(2026,7,1))+1))/$O71 -> 3960.9375 | R71: =$N71*MAX(0,(MIN($G71,DATE(2026,8,31))-MAX($E71,DATE(2026,8,1))+1))/$O71 -> 0 | S71: =$N71*MAX(0,(MIN($G71,DATE(2026,9,30))-MAX($E71,DATE(2026,9,1))+1))/$O71 -> 0 | T71: =$N71*MAX(0,(MIN($G71,DATE(2026,10,31))-MAX($E71,DATE(2026,10,1))+1))/$O71 -> 0 | U71: =$N71*MAX(0,(MIN($G71,DATE(2026,11,30))-MAX($E71,DATE(2026,11,1))+1))/$O71 -> 0 | V71: =$N71*MAX(0,(MIN($G71,DATE(2026,12,31))-MAX($E71,DATE(2026,12,1))+1))/$O71 -> 0 | W71: =$H71*MAX(0,(MIN($G71,DATE(2026,7,31))-MAX($E71,DATE(2026,7,1))+1))/30.4 -> 0.22203947 | X71: =$H71*MAX(0,(MIN($G71,DATE(2026,8,31))-MAX($E71,DATE(2026,8,1))+1))/30.4 -> 0 | Y71: =$H71*MAX(0,(MIN($G71,DATE(2026,9,30))-MAX($E71,DATE(2026,9,1))+1))/30.4 -> 0 | Z71: =$H71*MAX(0,(MIN($G71,DATE(2026,10,31))-MAX($E71,DATE(2026,10,1))+1))/30.4 -> 0 | AA71: =$H71*MAX(0,(MIN($G71,DATE(2026,11,30))-MAX($E71,DATE(2026,11,1))+1))/30.4 -> 0 | AB71: =$H71*MAX(0,(MIN($G71,DATE(2026,12,31))-MAX($E71,DATE(2026,12,1))+1))/30.4 -> 0
A72: 22 | B72: 5 | D72: SAC or AC | E72: 46195 | F72: 5 | G72: 46230 | H72: 1 | I72: Not Resourced | J72: =IFERROR(VLOOKUP(D72,Role_Mapping!$A$5:$D$31,2,FALSE()),"UNMAPPED") -> Senior Associate Consultant | K72: =IFERROR(VLOOKUP(D72,Role_Mapping!$A$5:$D$31,3,FALSE()),"IN") -> IN | L72: =IFERROR(SUMPRODUCT((Rate_Card!$A$5:$A$34=J72)*(Rate_Card!$B$5:$B$34=K72)*Rate_Card!$C$5:$C$34),0) -> 683 | M72: =F72*5 -> 25 | N72: =L72*M72*H72 -> 17075 | O72: =(G72-E72)+1 -> 36 | P72: =IFERROR(VLOOKUP(D72,Role_Mapping!$A$5:$D$31,4,FALSE()),"UNMAPPED") -> Consulting | Q72: =$N72*MAX(0,(MIN($G72,DATE(2026,7,31))-MAX($E72,DATE(2026,7,1))+1))/$O72 -> 12806.25 | R72: =$N72*MAX(0,(MIN($G72,DATE(2026,8,31))-MAX($E72,DATE(2026,8,1))+1))/$O72 -> 0 | S72: =$N72*MAX(0,(MIN($G72,DATE(2026,9,30))-MAX($E72,DATE(2026,9,1))+1))/$O72 -> 0 | T72: =$N72*MAX(0,(MIN($G72,DATE(2026,10,31))-MAX($E72,DATE(2026,10,1))+1))/$O72 -> 0 | U72: =$N72*MAX(0,(MIN($G72,DATE(2026,11,30))-MAX($E72,DATE(2026,11,1))+1))/$O72 -> 0 | V72: =$N72*MAX(0,(MIN($G72,DATE(2026,12,31))-MAX($E72,DATE(2026,12,1))+1))/$O72 -> 0 | W72: =$H72*MAX(0,(MIN($G72,DATE(2026,7,31))-MAX($E72,DATE(2026,7,1))+1))/30.4 -> 0.88815789 | X72: =$H72*MAX(0,(MIN($G72,DATE(2026,8,31))-MAX($E72,DATE(2026,8,1))+1))/30.4 -> 0 | Y72: =$H72*MAX(0,(MIN($G72,DATE(2026,9,30))-MAX($E72,DATE(2026,9,1))+1))/30.4 -> 0 | Z72: =$H72*MAX(0,(MIN($G72,DATE(2026,10,31))-MAX($E72,DATE(2026,10,1))+1))/30.4 -> 0 | AA72: =$H72*MAX(0,(MIN($G72,DATE(2026,11,30))-MAX($E72,DATE(2026,11,1))+1))/30.4 -> 0 | AB72: =$H72*MAX(0,(MIN($G72,DATE(2026,12,31))-MAX($E72,DATE(2026,12,1))+1))/30.4 -> 0
A73: 23 | B73: 5 | D73: Sol Con | E73: 46195 | F73: 5 | G73: 46230 | H73: 1 | I73: Not Resourced | J73: =IFERROR(VLOOKUP(D73,Role_Mapping!$A$5:$D$31,2,FALSE()),"UNMAPPED") -> Solutions Consultant | K73: =IFERROR(VLOOKUP(D73,Role_Mapping!$A$5:$D$31,3,FALSE()),"IN") -> IN | L73: =IFERROR(SUMPRODUCT((Rate_Card!$A$5:$A$34=J73)*(Rate_Card!$B$5:$B$34=K73)*Rate_Card!$C$5:$C$34),0) -> 683 | M73: =F73*5 -> 25 | N73: =L73*M73*H73 -> 17075 | O73: =(G73-E73)+1 -> 36 | P73: =IFERROR(VLOOKUP(D73,Role_Mapping!$A$5:$D$31,4,FALSE()),"UNMAPPED") -> Power BI & Consulting | Q73: =$N73*MAX(0,(MIN($G73,DATE(2026,7,31))-MAX($E73,DATE(2026,7,1))+1))/$O73 -> 12806.25 | R73: =$N73*MAX(0,(MIN($G73,DATE(2026,8,31))-MAX($E73,DATE(2026,8,1))+1))/$O73 -> 0 | S73: =$N73*MAX(0,(MIN($G73,DATE(2026,9,30))-MAX($E73,DATE(2026,9,1))+1))/$O73 -> 0 | T73: =$N73*MAX(0,(MIN($G73,DATE(2026,10,31))-MAX($E73,DATE(2026,10,1))+1))/$O73 -> 0 | U73: =$N73*MAX(0,(MIN($G73,DATE(2026,11,30))-MAX($E73,DATE(2026,11,1))+1))/$O73 -> 0 | V73: =$N73*MAX(0,(MIN($G73,DATE(2026,12,31))-MAX($E73,DATE(2026,12,1))+1))/$O73 -> 0 | W73: =$H73*MAX(0,(MIN($G73,DATE(2026,7,31))-MAX($E73,DATE(2026,7,1))+1))/30.4 -> 0.88815789 | X73: =$H73*MAX(0,(MIN($G73,DATE(2026,8,31))-MAX($E73,DATE(2026,8,1))+1))/30.4 -> 0 | Y73: =$H73*MAX(0,(MIN($G73,DATE(2026,9,30))-MAX($E73,DATE(2026,9,1))+1))/30.4 -> 0 | Z73: =$H73*MAX(0,(MIN($G73,DATE(2026,10,31))-MAX($E73,DATE(2026,10,1))+1))/30.4 -> 0 | AA73: =$H73*MAX(0,(MIN($G73,DATE(2026,11,30))-MAX($E73,DATE(2026,11,1))+1))/30.4 -> 0 | AB73: =$H73*MAX(0,(MIN($G73,DATE(2026,12,31))-MAX($E73,DATE(2026,12,1))+1))/30.4 -> 0
A74: 24 | B74: 5 | D74: SSE | E74: 46195 | F74: 5 | G74: 46230 | H74: 1 | I74: Not Resourced | J74: =IFERROR(VLOOKUP(D74,Role_Mapping!$A$5:$D$31,2,FALSE()),"UNMAPPED") -> Senior Software Engineer | K74: =IFERROR(VLOOKUP(D74,Role_Mapping!$A$5:$D$31,3,FALSE()),"IN") -> IN | L74: =IFERROR(SUMPRODUCT((Rate_Card!$A$5:$A$34=J74)*(Rate_Card!$B$5:$B$34=K74)*Rate_Card!$C$5:$C$34),0) -> 585 | M74: =F74*5 -> 25 | N74: =L74*M74*H74 -> 14625 | O74: =(G74-E74)+1 -> 36 | P74: =IFERROR(VLOOKUP(D74,Role_Mapping!$A$5:$D$31,4,FALSE()),"UNMAPPED") -> Full Stack | Q74: =$N74*MAX(0,(MIN($G74,DATE(2026,7,31))-MAX($E74,DATE(2026,7,1))+1))/$O74 -> 10968.75 | R74: =$N74*MAX(0,(MIN($G74,DATE(2026,8,31))-MAX($E74,DATE(2026,8,1))+1))/$O74 -> 0 | S74: =$N74*MAX(0,(MIN($G74,DATE(2026,9,30))-MAX($E74,DATE(2026,9,1))+1))/$O74 -> 0 | T74: =$N74*MAX(0,(MIN($G74,DATE(2026,10,31))-MAX($E74,DATE(2026,10,1))+1))/$O74 -> 0 | U74: =$N74*MAX(0,(MIN($G74,DATE(2026,11,30))-MAX($E74,DATE(2026,11,1))+1))/$O74 -> 0 | V74: =$N74*MAX(0,(MIN($G74,DATE(2026,12,31))-MAX($E74,DATE(2026,12,1))+1))/$O74 -> 0 | W74: =$H74*MAX(0,(MIN($G74,DATE(2026,7,31))-MAX($E74,DATE(2026,7,1))+1))/30.4 -> 0.88815789 | X74: =$H74*MAX(0,(MIN($G74,DATE(2026,8,31))-MAX($E74,DATE(2026,8,1))+1))/30.4 -> 0 | Y74: =$H74*MAX(0,(MIN($G74,DATE(2026,9,30))-MAX($E74,DATE(2026,9,1))+1))/30.4 -> 0 | Z74: =$H74*MAX(0,(MIN($G74,DATE(2026,10,31))-MAX($E74,DATE(2026,10,1))+1))/30.4 -> 0 | AA74: =$H74*MAX(0,(MIN($G74,DATE(2026,11,30))-MAX($E74,DATE(2026,11,1))+1))/30.4 -> 0 | AB74: =$H74*MAX(0,(MIN($G74,DATE(2026,12,31))-MAX($E74,DATE(2026,12,1))+1))/30.4 -> 0
A75: 25 | B75: 5 | D75: SE | E75: 46195 | F75: 5 | G75: 46230 | H75: 1 | I75: Not Resourced | J75: =IFERROR(VLOOKUP(D75,Role_Mapping!$A$5:$D$31,2,FALSE()),"UNMAPPED") -> Software Engineer | K75: =IFERROR(VLOOKUP(D75,Role_Mapping!$A$5:$D$31,3,FALSE()),"IN") -> IN | L75: =IFERROR(SUMPRODUCT((Rate_Card!$A$5:$A$34=J75)*(Rate_Card!$B$5:$B$34=K75)*Rate_Card!$C$5:$C$34),0) -> 455 | M75: =F75*5 -> 25 | N75: =L75*M75*H75 -> 11375 | O75: =(G75-E75)+1 -> 36 | P75: =IFERROR(VLOOKUP(D75,Role_Mapping!$A$5:$D$31,4,FALSE()),"UNMAPPED") -> Full Stack | Q75: =$N75*MAX(0,(MIN($G75,DATE(2026,7,31))-MAX($E75,DATE(2026,7,1))+1))/$O75 -> 8531.25 | R75: =$N75*MAX(0,(MIN($G75,DATE(2026,8,31))-MAX($E75,DATE(2026,8,1))+1))/$O75 -> 0 | S75: =$N75*MAX(0,(MIN($G75,DATE(2026,9,30))-MAX($E75,DATE(2026,9,1))+1))/$O75 -> 0 | T75: =$N75*MAX(0,(MIN($G75,DATE(2026,10,31))-MAX($E75,DATE(2026,10,1))+1))/$O75 -> 0 | U75: =$N75*MAX(0,(MIN($G75,DATE(2026,11,30))-MAX($E75,DATE(2026,11,1))+1))/$O75 -> 0 | V75: =$N75*MAX(0,(MIN($G75,DATE(2026,12,31))-MAX($E75,DATE(2026,12,1))+1))/$O75 -> 0 | W75: =$H75*MAX(0,(MIN($G75,DATE(2026,7,31))-MAX($E75,DATE(2026,7,1))+1))/30.4 -> 0.88815789 | X75: =$H75*MAX(0,(MIN($G75,DATE(2026,8,31))-MAX($E75,DATE(2026,8,1))+1))/30.4 -> 0 | Y75: =$H75*MAX(0,(MIN($G75,DATE(2026,9,30))-MAX($E75,DATE(2026,9,1))+1))/30.4 -> 0 | Z75: =$H75*MAX(0,(MIN($G75,DATE(2026,10,31))-MAX($E75,DATE(2026,10,1))+1))/30.4 -> 0 | AA75: =$H75*MAX(0,(MIN($G75,DATE(2026,11,30))-MAX($E75,DATE(2026,11,1))+1))/30.4 -> 0 | AB75: =$H75*MAX(0,(MIN($G75,DATE(2026,12,31))-MAX($E75,DATE(2026,12,1))+1))/30.4 -> 0
A76: 26 | B76: 5 | C76: KIA | D76: AP | E76: 46195 | F76: 5 | G76: 46230 | H76: 0.125 | I76: Resourced | J76: =IFERROR(VLOOKUP(D76,Role_Mapping!$A$5:$D$31,2,FALSE()),"UNMAPPED") -> Associate Partner | K76: =IFERROR(VLOOKUP(D76,Role_Mapping!$A$5:$D$31,3,FALSE()),"IN") -> UK | L76: =IFERROR(SUMPRODUCT((Rate_Card!$A$5:$A$34=J76)*(Rate_Card!$B$5:$B$34=K76)*Rate_Card!$C$5:$C$34),0) -> 3526 | M76: =F76*5 -> 25 | N76: =L76*M76*H76 -> 11018.75 | O76: =(G76-E76)+1 -> 36 | P76: =IFERROR(VLOOKUP(D76,Role_Mapping!$A$5:$D$31,4,FALSE()),"UNMAPPED") -> GTM | Q76: =$N76*MAX(0,(MIN($G76,DATE(2026,7,31))-MAX($E76,DATE(2026,7,1))+1))/$O76 -> 8264.0625 | R76: =$N76*MAX(0,(MIN($G76,DATE(2026,8,31))-MAX($E76,DATE(2026,8,1))+1))/$O76 -> 0 | S76: =$N76*MAX(0,(MIN($G76,DATE(2026,9,30))-MAX($E76,DATE(2026,9,1))+1))/$O76 -> 0 | T76: =$N76*MAX(0,(MIN($G76,DATE(2026,10,31))-MAX($E76,DATE(2026,10,1))+1))/$O76 -> 0 | U76: =$N76*MAX(0,(MIN($G76,DATE(2026,11,30))-MAX($E76,DATE(2026,11,1))+1))/$O76 -> 0 | V76: =$N76*MAX(0,(MIN($G76,DATE(2026,12,31))-MAX($E76,DATE(2026,12,1))+1))/$O76 -> 0 | W76: =$H76*MAX(0,(MIN($G76,DATE(2026,7,31))-MAX($E76,DATE(2026,7,1))+1))/30.4 -> 0.11101974 | X76: =$H76*MAX(0,(MIN($G76,DATE(2026,8,31))-MAX($E76,DATE(2026,8,1))+1))/30.4 -> 0 | Y76: =$H76*MAX(0,(MIN($G76,DATE(2026,9,30))-MAX($E76,DATE(2026,9,1))+1))/30.4 -> 0 | Z76: =$H76*MAX(0,(MIN($G76,DATE(2026,10,31))-MAX($E76,DATE(2026,10,1))+1))/30.4 -> 0 | AA76: =$H76*MAX(0,(MIN($G76,DATE(2026,11,30))-MAX($E76,DATE(2026,11,1))+1))/30.4 -> 0 | AB76: =$H76*MAX(0,(MIN($G76,DATE(2026,12,31))-MAX($E76,DATE(2026,12,1))+1))/30.4 -> 0
A77: 27 | B77: 5 | D77: M | E77: 46195 | F77: 5 | G77: 46230 | H77: 0.5 | I77: Resourced | J77: =IFERROR(VLOOKUP(D77,Role_Mapping!$A$5:$D$31,2,FALSE()),"UNMAPPED") -> Manager | K77: =IFERROR(VLOOKUP(D77,Role_Mapping!$A$5:$D$31,3,FALSE()),"IN") -> UK | L77: =IFERROR(SUMPRODUCT((Rate_Card!$A$5:$A$34=J77)*(Rate_Card!$B$5:$B$34=K77)*Rate_Card!$C$5:$C$34),0) -> 2984 | M77: =F77*5 -> 25 | N77: =L77*M77*H77 -> 37300 | O77: =(G77-E77)+1 -> 36 | P77: =IFERROR(VLOOKUP(D77,Role_Mapping!$A$5:$D$31,4,FALSE()),"UNMAPPED") -> Consulting | Q77: =$N77*MAX(0,(MIN($G77,DATE(2026,7,31))-MAX($E77,DATE(2026,7,1))+1))/$O77 -> 27975 | R77: =$N77*MAX(0,(MIN($G77,DATE(2026,8,31))-MAX($E77,DATE(2026,8,1))+1))/$O77 -> 0 | S77: =$N77*MAX(0,(MIN($G77,DATE(2026,9,30))-MAX($E77,DATE(2026,9,1))+1))/$O77 -> 0 | T77: =$N77*MAX(0,(MIN($G77,DATE(2026,10,31))-MAX($E77,DATE(2026,10,1))+1))/$O77 -> 0 | U77: =$N77*MAX(0,(MIN($G77,DATE(2026,11,30))-MAX($E77,DATE(2026,11,1))+1))/$O77 -> 0 | V77: =$N77*MAX(0,(MIN($G77,DATE(2026,12,31))-MAX($E77,DATE(2026,12,1))+1))/$O77 -> 0 | W77: =$H77*MAX(0,(MIN($G77,DATE(2026,7,31))-MAX($E77,DATE(2026,7,1))+1))/30.4 -> 0.44407895 | X77: =$H77*MAX(0,(MIN($G77,DATE(2026,8,31))-MAX($E77,DATE(2026,8,1))+1))/30.4 -> 0 | Y77: =$H77*MAX(0,(MIN($G77,DATE(2026,9,30))-MAX($E77,DATE(2026,9,1))+1))/30.4 -> 0 | Z77: =$H77*MAX(0,(MIN($G77,DATE(2026,10,31))-MAX($E77,DATE(2026,10,1))+1))/30.4 -> 0 | AA77: =$H77*MAX(0,(MIN($G77,DATE(2026,11,30))-MAX($E77,DATE(2026,11,1))+1))/30.4 -> 0 | AB77: =$H77*MAX(0,(MIN($G77,DATE(2026,12,31))-MAX($E77,DATE(2026,12,1))+1))/30.4 -> 0
A78: 28 | B78: 5 | D78: C | E78: 46195 | F78: 5 | G78: 46230 | H78: 1 | I78: Resourced | J78: =IFERROR(VLOOKUP(D78,Role_Mapping!$A$5:$D$31,2,FALSE()),"UNMAPPED") -> Consultant | K78: =IFERROR(VLOOKUP(D78,Role_Mapping!$A$5:$D$31,3,FALSE()),"IN") -> IN | L78: =IFERROR(SUMPRODUCT((Rate_Card!$A$5:$A$34=J78)*(Rate_Card!$B$5:$B$34=K78)*Rate_Card!$C$5:$C$34),0) -> 683 | M78: =F78*5 -> 25 | N78: =L78*M78*H78 -> 17075 | O78: =(G78-E78)+1 -> 36 | P78: =IFERROR(VLOOKUP(D78,Role_Mapping!$A$5:$D$31,4,FALSE()),"UNMAPPED") -> Consulting | Q78: =$N78*MAX(0,(MIN($G78,DATE(2026,7,31))-MAX($E78,DATE(2026,7,1))+1))/$O78 -> 12806.25 | R78: =$N78*MAX(0,(MIN($G78,DATE(2026,8,31))-MAX($E78,DATE(2026,8,1))+1))/$O78 -> 0 | S78: =$N78*MAX(0,(MIN($G78,DATE(2026,9,30))-MAX($E78,DATE(2026,9,1))+1))/$O78 -> 0 | T78: =$N78*MAX(0,(MIN($G78,DATE(2026,10,31))-MAX($E78,DATE(2026,10,1))+1))/$O78 -> 0 | U78: =$N78*MAX(0,(MIN($G78,DATE(2026,11,30))-MAX($E78,DATE(2026,11,1))+1))/$O78 -> 0 | V78: =$N78*MAX(0,(MIN($G78,DATE(2026,12,31))-MAX($E78,DATE(2026,12,1))+1))/$O78 -> 0 | W78: =$H78*MAX(0,(MIN($G78,DATE(2026,7,31))-MAX($E78,DATE(2026,7,1))+1))/30.4 -> 0.88815789 | X78: =$H78*MAX(0,(MIN($G78,DATE(2026,8,31))-MAX($E78,DATE(2026,8,1))+1))/30.4 -> 0 | Y78: =$H78*MAX(0,(MIN($G78,DATE(2026,9,30))-MAX($E78,DATE(2026,9,1))+1))/30.4 -> 0 | Z78: =$H78*MAX(0,(MIN($G78,DATE(2026,10,31))-MAX($E78,DATE(2026,10,1))+1))/30.4 -> 0 | AA78: =$H78*MAX(0,(MIN($G78,DATE(2026,11,30))-MAX($E78,DATE(2026,11,1))+1))/30.4 -> 0 | AB78: =$H78*MAX(0,(MIN($G78,DATE(2026,12,31))-MAX($E78,DATE(2026,12,1))+1))/30.4 -> 0
A79: 29 | B79: 5 | D79: PA | E79: 46195 | F79: 5 | G79: 46230 | H79: 0.25 | I79: Not Resourced | J79: =IFERROR(VLOOKUP(D79,Role_Mapping!$A$5:$D$31,2,FALSE()),"UNMAPPED") -> Principal Technology Architect | K79: =IFERROR(VLOOKUP(D79,Role_Mapping!$A$5:$D$31,3,FALSE()),"IN") -> IN | L79: =IFERROR(SUMPRODUCT((Rate_Card!$A$5:$A$34=J79)*(Rate_Card!$B$5:$B$34=K79)*Rate_Card!$C$5:$C$34),0) -> 845 | M79: =F79*5 -> 25 | N79: =L79*M79*H79 -> 5281.25 | O79: =(G79-E79)+1 -> 36 | P79: =IFERROR(VLOOKUP(D79,Role_Mapping!$A$5:$D$31,4,FALSE()),"UNMAPPED") -> Full Stack | Q79: =$N79*MAX(0,(MIN($G79,DATE(2026,7,31))-MAX($E79,DATE(2026,7,1))+1))/$O79 -> 3960.9375 | R79: =$N79*MAX(0,(MIN($G79,DATE(2026,8,31))-MAX($E79,DATE(2026,8,1))+1))/$O79 -> 0 | S79: =$N79*MAX(0,(MIN($G79,DATE(2026,9,30))-MAX($E79,DATE(2026,9,1))+1))/$O79 -> 0 | T79: =$N79*MAX(0,(MIN($G79,DATE(2026,10,31))-MAX($E79,DATE(2026,10,1))+1))/$O79 -> 0 | U79: =$N79*MAX(0,(MIN($G79,DATE(2026,11,30))-MAX($E79,DATE(2026,11,1))+1))/$O79 -> 0 | V79: =$N79*MAX(0,(MIN($G79,DATE(2026,12,31))-MAX($E79,DATE(2026,12,1))+1))/$O79 -> 0 | W79: =$H79*MAX(0,(MIN($G79,DATE(2026,7,31))-MAX($E79,DATE(2026,7,1))+1))/30.4 -> 0.22203947 | X79: =$H79*MAX(0,(MIN($G79,DATE(2026,8,31))-MAX($E79,DATE(2026,8,1))+1))/30.4 -> 0 | Y79: =$H79*MAX(0,(MIN($G79,DATE(2026,9,30))-MAX($E79,DATE(2026,9,1))+1))/30.4 -> 0 | Z79: =$H79*MAX(0,(MIN($G79,DATE(2026,10,31))-MAX($E79,DATE(2026,10,1))+1))/30.4 -> 0 | AA79: =$H79*MAX(0,(MIN($G79,DATE(2026,11,30))-MAX($E79,DATE(2026,11,1))+1))/30.4 -> 0 | AB79: =$H79*MAX(0,(MIN($G79,DATE(2026,12,31))-MAX($E79,DATE(2026,12,1))+1))/30.4 -> 0
A80: 30 | B80: 5 | D80: Sol Con | E80: 46195 | F80: 5 | G80: 46230 | H80: 1 | I80: Not Resourced | J80: =IFERROR(VLOOKUP(D80,Role_Mapping!$A$5:$D$31,2,FALSE()),"UNMAPPED") -> Solutions Consultant | K80: =IFERROR(VLOOKUP(D80,Role_Mapping!$A$5:$D$31,3,FALSE()),"IN") -> IN | L80: =IFERROR(SUMPRODUCT((Rate_Card!$A$5:$A$34=J80)*(Rate_Card!$B$5:$B$34=K80)*Rate_Card!$C$5:$C$34),0) -> 683 | M80: =F80*5 -> 25 | N80: =L80*M80*H80 -> 17075 | O80: =(G80-E80)+1 -> 36 | P80: =IFERROR(VLOOKUP(D80,Role_Mapping!$A$5:$D$31,4,FALSE()),"UNMAPPED") -> Power BI & Consulting | Q80: =$N80*MAX(0,(MIN($G80,DATE(2026,7,31))-MAX($E80,DATE(2026,7,1))+1))/$O80 -> 12806.25 | R80: =$N80*MAX(0,(MIN($G80,DATE(2026,8,31))-MAX($E80,DATE(2026,8,1))+1))/$O80 -> 0 | S80: =$N80*MAX(0,(MIN($G80,DATE(2026,9,30))-MAX($E80,DATE(2026,9,1))+1))/$O80 -> 0 | T80: =$N80*MAX(0,(MIN($G80,DATE(2026,10,31))-MAX($E80,DATE(2026,10,1))+1))/$O80 -> 0 | U80: =$N80*MAX(0,(MIN($G80,DATE(2026,11,30))-MAX($E80,DATE(2026,11,1))+1))/$O80 -> 0 | V80: =$N80*MAX(0,(MIN($G80,DATE(2026,12,31))-MAX($E80,DATE(2026,12,1))+1))/$O80 -> 0 | W80: =$H80*MAX(0,(MIN($G80,DATE(2026,7,31))-MAX($E80,DATE(2026,7,1))+1))/30.4 -> 0.88815789 | X80: =$H80*MAX(0,(MIN($G80,DATE(2026,8,31))-MAX($E80,DATE(2026,8,1))+1))/30.4 -> 0 | Y80: =$H80*MAX(0,(MIN($G80,DATE(2026,9,30))-MAX($E80,DATE(2026,9,1))+1))/30.4 -> 0 | Z80: =$H80*MAX(0,(MIN($G80,DATE(2026,10,31))-MAX($E80,DATE(2026,10,1))+1))/30.4 -> 0 | AA80: =$H80*MAX(0,(MIN($G80,DATE(2026,11,30))-MAX($E80,DATE(2026,11,1))+1))/30.4 -> 0 | AB80: =$H80*MAX(0,(MIN($G80,DATE(2026,12,31))-MAX($E80,DATE(2026,12,1))+1))/30.4 -> 0
A81: 31 | B81: 5 | D81: SE | E81: 46195 | F81: 5 | G81: 46230 | H81: 1 | I81: Not Resourced | J81: =IFERROR(VLOOKUP(D81,Role_Mapping!$A$5:$D$31,2,FALSE()),"UNMAPPED") -> Software Engineer | K81: =IFERROR(VLOOKUP(D81,Role_Mapping!$A$5:$D$31,3,FALSE()),"IN") -> IN | L81: =IFERROR(SUMPRODUCT((Rate_Card!$A$5:$A$34=J81)*(Rate_Card!$B$5:$B$34=K81)*Rate_Card!$C$5:$C$34),0) -> 455 | M81: =F81*5 -> 25 | N81: =L81*M81*H81 -> 11375 | O81: =(G81-E81)+1 -> 36 | P81: =IFERROR(VLOOKUP(D81,Role_Mapping!$A$5:$D$31,4,FALSE()),"UNMAPPED") -> Full Stack | Q81: =$N81*MAX(0,(MIN($G81,DATE(2026,7,31))-MAX($E81,DATE(2026,7,1))+1))/$O81 -> 8531.25 | R81: =$N81*MAX(0,(MIN($G81,DATE(2026,8,31))-MAX($E81,DATE(2026,8,1))+1))/$O81 -> 0 | S81: =$N81*MAX(0,(MIN($G81,DATE(2026,9,30))-MAX($E81,DATE(2026,9,1))+1))/$O81 -> 0 | T81: =$N81*MAX(0,(MIN($G81,DATE(2026,10,31))-MAX($E81,DATE(2026,10,1))+1))/$O81 -> 0 | U81: =$N81*MAX(0,(MIN($G81,DATE(2026,11,30))-MAX($E81,DATE(2026,11,1))+1))/$O81 -> 0 | V81: =$N81*MAX(0,(MIN($G81,DATE(2026,12,31))-MAX($E81,DATE(2026,12,1))+1))/$O81 -> 0 | W81: =$H81*MAX(0,(MIN($G81,DATE(2026,7,31))-MAX($E81,DATE(2026,7,1))+1))/30.4 -> 0.88815789 | X81: =$H81*MAX(0,(MIN($G81,DATE(2026,8,31))-MAX($E81,DATE(2026,8,1))+1))/30.4 -> 0 | Y81: =$H81*MAX(0,(MIN($G81,DATE(2026,9,30))-MAX($E81,DATE(2026,9,1))+1))/30.4 -> 0 | Z81: =$H81*MAX(0,(MIN($G81,DATE(2026,10,31))-MAX($E81,DATE(2026,10,1))+1))/30.4 -> 0 | AA81: =$H81*MAX(0,(MIN($G81,DATE(2026,11,30))-MAX($E81,DATE(2026,11,1))+1))/30.4 -> 0 | AB81: =$H81*MAX(0,(MIN($G81,DATE(2026,12,31))-MAX($E81,DATE(2026,12,1))+1))/30.4 -> 0
