Workbook

Sheet Forecast
A1: Cluster | B1: Request Received | C1: Original Requested Start Date | D1: Request Type | E1: Client Priority | F1: Client | G1: EM | H1: Likely Start Date | I1: Start Date Confirmed | J1: Number of Weeks | K1: Deal Stage (HubSpot) | L1: Solution | M1: Priority | N1: Status | O1: Resources Requested | P1: % | Q1: Resource Recommended | R1: % Available | S1: Skillset | T1: Skillset Match (Complete / Partial / No) | U1: SOW Signed | V1: Comments
A2: 3 | B2: 46070 | C2: 46132 | D2: New | E2: Gold | F2: Sigma | G2: XYXY | H2: 46209 | I2: No | J2: 11 | K2: Scoping Approval | L2: Value Creation | M2: Medium | N2: Not Resourced | O2: P | P2: 25 | U2: No | V2: It isn't solidified yet but requires very specific skillsets. I have pre-emptively engaged with CoE leads and Cluster leads of the required personnel - from Chris
A3: 3 | C3: 46132 | H3: 46209 | M3: Medium | N3: Not Resourced | O3: SC | P3: 50
A4: 3 | C4: 46132 | H4: 46209 | M4: Medium | N4: Not Resourced | O4: C | P4: 100
A5: 3 | C5: 46132 | H5: 46209 | M5: Medium | N5: Not Resourced | O5: Sr Sol Con | P5: 75/100 | S5: {=INDEX(Skillset!$C$2:$C$101, MOD(ROW()-2, 100)+1)} -> PII handling, Scalable execution environments, Incremental loads & CDC | V5: Extensive snowflake experience is required
A6: 3 | C6: 46132 | H6: 46209 | M6: Medium | N6: Not Resourced | O6: SSE | P6: 100 | S6: {=INDEX(Skillset!$C$2:$C$101, MOD(ROW()-2, 100)+1)} -> Data preparation for decision making report, Anomaly detection, LTV (Life Time Value)
A7: 3 | C7: 46132 | H7: 46209 | M7: Medium | N7: Not Resourced | O7: SE | P7: 100 | S7: {=INDEX(Skillset!$C$2:$C$101, MOD(ROW()-2, 100)+1)} -> Industry Knowledge - Understanding of the specific industry or market, industry trends, challenges, and best practices., Communication Skills - Ability to present findings and insights to technical and non-technical stakeholders., Data Visualization Tools - Experience with BI tools like Tableau, Power BI, or QlikView.
A8: 5 | B8: 46077 | C8: 46132 | E8: Gold | F8: Spidy | G8: XYXY | H8: 46209 | K8: Signed | L8: Due Diligence | M8: Medium | N8: Not Resourced | O8: Enabler | P8: 12.5 | S8: {=INDEX(Skillset!$C$2:$C$101, MOD(ROW()-2, 100)+1)} -> Pipeline design principles, Workspace, environment & compute management, Project scoping & planning
A9: 5 | C9: 46132 | H9: 46209 | I9: Yes | J9: 4 | M9: Medium | N9: Not Resourced | O9: Sol Con | P9: 50 | S9: {=INDEX(Skillset!$C$2:$C$101, MOD(ROW()-2, 100)+1)} -> Programming Languages - Familiarity with scripting languages for automation., Problem-Solving Skills - Proficiency in identifying issues and developing solutions with creative thinking to approach problems from different angles., SQL Proficiency-Ability to write complex queries and optimize them for performance.
A10: 5 | C10: 46132 | H10: 46209 | M10: Medium | N10: Not Resourced | O10: SE | P10: 100 | S10: {=INDEX(Skillset!$C$2:$C$101, MOD(ROW()-2, 100)+1)} -> integrations, Network Security, Monitoring
A11: 4 | B11: 46107 | C11: 46132 | D11: New | E11: Other | F11: FD | G11: XYXY | H11: 46209 | I11: No | J11: 5 | K11: Build the Proposition | M11: High | N11: Not Resourced | O11: AP/P | P11: 37.5 | U11: No
A12: 4 | C12: 46132 | H12: 46209 | M12: High | N12: Not Resourced | O12: PA | P12: 25
A13: 4 | C13: 46132 | H13: 46209 | M13: High | N13: Not Resourced | O13: SC (EM) | P13: 50 | V13: strong EM with Discovery & Design experience
A14: 4 | C14: 46132 | H14: 46209 | M14: High | N14: Not Resourced | O14: SAC | P14: 100 | V14: strong SAC with Discovery & Design experience
A15: 4 | C15: 46132 | H15: 46209 | L15: Core Reporting | M15: High | N15: Not Resourced | O15: SAC | P15: 100 | V15: strong SAC with business process change experience - one SAC for the dashboard design and one SAC for business process change (an additional workstream that is not typically included in our D&D phase.
A16: 4 | C16: 46132 | H16: 46209 | M16: High | N16: Not Resourced | O16: Sol Con | P16: 100 | S16: {=INDEX(Skillset!$C$2:$C$101, MOD(ROW()-2, 100)+1)} -> GraphQL, JavaScript, API Security best practices | V16: Discovery & Design experience
A17: 4 | C17: 46132 | H17: 46209 | M17: High | N17: Not Resourced | O17: Enabler | P17: 100 | S17: {=INDEX(Skillset!$C$2:$C$101, MOD(ROW()-2, 100)+1)} -> Kubernetes, security groups, Tracing | V17: Discovery & Design experience
A18: 4 | C18: 46132 | H18: 46209 | M18: High | N18: Not Resourced | O18: SSE | P18: 100 | S18: {=INDEX(Skillset!$C$2:$C$101, MOD(ROW()-2, 100)+1)} -> Retry & exponential backoff logic, User-agent rotation, Audit logging for traceability | V18: with data gap assessment or Discovery & Design experience (100%)
A19: 5 | B19: 46107 | C19: 46132 | D19: New | E19: Gold | F19: HD | G19: XYXY | H19: 46223 | I19: No | J19: 5 | K19: Build the Proposition | L19: Core Reporting | M19: Low | N19: Part Resourced | O19: AP | P19: 12.5 | U19: No
A20: 5 | C20: 46132 | H20: 46223 | M20: Low | N20: Part Resourced | O20: M | P20: 50
A21: 5 | C21: 46132 | H21: 46223 | M21: Low | N21: Part Resourced | O21: SC | P21: 50
A22: 5 | C22: 46132 | H22: 46223 | M22: Low | N22: Part Resourced | O22: SAC | P22: 100 | V22: could we use AC?
A23: 5 | C23: 46132 | H23: 46223 | M23: Low | N23: Not Resourced | O23: PA | P23: 25
A24: 5 | C24: 46132 | H24: 46223 | M24: Low | N24: Not Resourced | O24: Sol Con | P24: 100 | S24: {=INDEX(Skillset!$C$2:$C$101, MOD(ROW()-2, 100)+1)} -> Azure, Lakehouse & Warehouse Architecture patterns, Lakehouse & Warehouse Architecture patterns
A25: 3 | B25: 46077 | C25: 46090 | D25: New | E25: Other | F25: Alpha | G25: XYXY | H25: 46265 | I25: No | J25: 3 | L25: Exit Support | M25: Low | N25: Not Resourced | O25: P | P25: 12.5 | U25: Yes
A26: 3 | C26: 46090 | H26: 46265 | M26: Low | N26: Not Resourced | O26: PA | P26: 25
A27: 3 | C27: 46090 | H27: 46265 | M27: Low | N27: Not Resourced | O27: EM | P27: 50 | V27: Already assigned to PureFin - has 50% available
A28: 3 | C28: 46090 | H28: 46265 | M28: Low | N28: Not Resourced | O28: SAC | P28: 100
A29: 3 | C29: 46090 | H29: 46265 | M29: Low | N29: Not Resourced | O29: AC | P29: 100 | V29: new hire
A30: 3 | C30: 46090 | H30: 46265 | M30: Low | N30: Not Resourced | O30: Sol Con | P30: 100 | S30: {=INDEX(Skillset!$C$2:$C$101, MOD(ROW()-2, 100)+1)} -> Bicep, Policy as code, Network Security
A31: 3 | C31: 46090 | H31: 46265 | M31: Low | N31: Not Resourced | O31: SSE | P31: 100 | S31: {=INDEX(Skillset!$C$2:$C$101, MOD(ROW()-2, 100)+1)} -> Tracing, security groups, REST APIs
A32: 3 | C32: 46160 | E32: Gold | F32: Pappa Jones | H32: 46204 | K32: Build the Proposition | M32: Low | N32: Not Resourced | O32: SAC | P32: 100 | U32: No
A33: 5 | B33: 46128 | C33: 46160 | D33: Next Phase | E33: Gold | F33: Mcd | H33: 46223 | I33: No | J33: 7 | K33: Signed | L33: Due Diligence | M33: Low | N33: Not Resourced | O33: AC | P33: 100
A34: 5 | C34: 46160 | E34: Gold | H34: 46223 | M34: Low | N34: Not Resourced | O34: Enabler | P34: 100 | S34: {=INDEX(Skillset!$C$2:$C$101, MOD(ROW()-2, 100)+1)} -> CI/CD Pipelines, Mobile-friendly architecture, Agile manifesto & principles
A35: 5 | C35: 46160 | E35: Gold | H35: 46223 | M35: Low | N35: Not Resourced | O35: SE | P35: 100 | S35: {=INDEX(Skillset!$C$2:$C$101, MOD(ROW()-2, 100)+1)} -> Business Acumen - Understanding of business processes and metrics to align BI solutions with business goals and strategies., Time Management - Strong organizational skills to manage multiple projects and priorities., Business Acumen - Understanding of business processes and metrics to align BI solutions with business goals and strategies.
A36: 5 | B36: 46135 | C36: 46160 | E36: Silver | F36: Pepsi | H36: 46216 | I36: No | J36: 16 | L36: Exit Support | M36: High | N36: Not Resourced | O36: SC | P36: 25
A37: 5 | C37: 46160 | E37: Silver | H37: 46216 | M37: High | N37: Not Resourced | O37: SAC | P37: 100
A38: 5 | C38: 46160 | E38: Silver | H38: 46216 | M38: High | N38: Not Resourced | O38: PA | P38: 12.5
A39: 5 | C39: 46160 | E39: Silver | H39: 46216 | M39: High | N39: Not Resourced | O39: Sol Con | P39: 50 | S39: {=INDEX(Skillset!$C$2:$C$101, MOD(ROW()-2, 100)+1)} -> Dimensional, Lakehouse & Warehouse Architecture patterns, Snowflake with dbt
A40: 5 | C40: 46160 | E40: Silver | H40: 46216 | M40: High | N40: Not Resourced | O40: Enabler | P40: 100 | S40: {=INDEX(Skillset!$C$2:$C$101, MOD(ROW()-2, 100)+1)} -> Dimensional, AWS, Data observability
...

Sheet Skillset
A1: Row # | B1: COE Skill | C1: Skills (Combined) | D1: COE Skills List
A2: 1 | B2: {=INDEX(_xlfn.ANCHORARRAY($D$2),RANDBETWEEN(1,COUNTA(_xlfn.ANCHORARRAY($D$2))))} -> Data Engineering | C2: Programming Languages - Familiarity with scripting languages for automation., Business Acumen - Understanding of business processes and metrics to align BI solutions with business goals and strategies., Data Warehousing- Understanding of data warehousing concepts and architecture. | D2: {=_xlfn.UNIQUE('[1]Consolidated skill data'!B2:B82212)} -> Data Science & AI
A3: 2 | B3: {=INDEX(_xlfn.ANCHORARRAY($D$2),RANDBETWEEN(1,COUNTA(_xlfn.ANCHORARRAY($D$2))))} -> Full Stack | C3: LlamaIndex, Survival Analysis (CPH), ML Flow | D3: Full Stack
A4: 3 | B4: {=INDEX(_xlfn.ANCHORARRAY($D$2),RANDBETWEEN(1,COUNTA(_xlfn.ANCHORARRAY($D$2))))} -> TechOps and Automation | C4: Monitoring, Network Security, Logging | D4: BI & Reporting, Consulting
A5: 4 | B5: {=INDEX(_xlfn.ANCHORARRAY($D$2),RANDBETWEEN(1,COUNTA(_xlfn.ANCHORARRAY($D$2))))} -> Data Science & AI | C5: PII handling, Scalable execution environments, Incremental loads & CDC | D5: Data Engineering
A6: 5 | B6: {=INDEX(_xlfn.ANCHORARRAY($D$2),RANDBETWEEN(1,COUNTA(_xlfn.ANCHORARRAY($D$2))))} -> Full Stack | C6: Data preparation for decision making report, Anomaly detection, LTV (Life Time Value) | D6: Platform Engineering
A7: 6 | B7: {=INDEX(_xlfn.ANCHORARRAY($D$2),RANDBETWEEN(1,COUNTA(_xlfn.ANCHORARRAY($D$2))))} -> BI & Reporting, Consulting | C7: Industry Knowledge - Understanding of the specific industry or market, industry trends, challenges, and best practices., Communication Skills - Ability to present findings and insights to technical and non-technical stakeholders., Data Visualization Tools - Experience with BI tools like Tableau, Power BI, or QlikView. | D7: TechOps and Automation
A8: 7 | B8: {=INDEX(_xlfn.ANCHORARRAY($D$2),RANDBETWEEN(1,COUNTA(_xlfn.ANCHORARRAY($D$2))))} -> Full Stack | C8: Pipeline design principles, Workspace, environment & compute management, Project scoping & planning
A9: 8 | B9: {=INDEX(_xlfn.ANCHORARRAY($D$2),RANDBETWEEN(1,COUNTA(_xlfn.ANCHORARRAY($D$2))))} -> Data Engineering | C9: Programming Languages - Familiarity with scripting languages for automation., Problem-Solving Skills - Proficiency in identifying issues and developing solutions with creative thinking to approach problems from different angles., SQL Proficiency-Ability to write complex queries and optimize them for performance.
A10: 9 | B10: {=INDEX(_xlfn.ANCHORARRAY($D$2),RANDBETWEEN(1,COUNTA(_xlfn.ANCHORARRAY($D$2))))} -> BI & Reporting, Consulting | C10: integrations, Network Security, Monitoring
A11: 10 | B11: {=INDEX(_xlfn.ANCHORARRAY($D$2),RANDBETWEEN(1,COUNTA(_xlfn.ANCHORARRAY($D$2))))} -> Full Stack | C11: Business Acumen - Understanding of business processes and metrics to align BI solutions with business goals and strategies., Communication Skills - Ability to present findings and insights to technical and non-technical stakeholders., Data Warehousing- Understanding of data warehousing concepts and architecture.
A12: 11 | B12: {=INDEX(_xlfn.ANCHORARRAY($D$2),RANDBETWEEN(1,COUNTA(_xlfn.ANCHORARRAY($D$2))))} -> Data Science & AI | C12: Understanding of how to handle large volumes of data. - Handelling large data volumes, Data Warehousing- Understanding of data warehousing concepts and architecture., Programming Languages - Familiarity with scripting languages for automation.
A13: 12 | B13: {=INDEX(_xlfn.ANCHORARRAY($D$2),RANDBETWEEN(1,COUNTA(_xlfn.ANCHORARRAY($D$2))))} -> Platform Engineering | C13: Statistical Foundations, Large Language Models (LLMs)., Bias detection tools
A14: 13 | B14: {=INDEX(_xlfn.ANCHORARRAY($D$2),RANDBETWEEN(1,COUNTA(_xlfn.ANCHORARRAY($D$2))))} -> BI & Reporting, Consulting | C14: SQL, Cloud AI Platform, Dashbaord integration into salesforce
A15: 14 | B15: {=INDEX(_xlfn.ANCHORARRAY($D$2),RANDBETWEEN(1,COUNTA(_xlfn.ANCHORARRAY($D$2))))} -> BI & Reporting, Consulting | C15: Project Management - Skills in planning, executing, and managing projects to meet deadlines and manage resources effectively., Adaptability - Flexibility to adapt to changing client needs and environments., Project Management - Skills in planning, executing, and managing projects to meet deadlines and manage resources effectively.
A16: 15 | B16: {=INDEX(_xlfn.ANCHORARRAY($D$2),RANDBETWEEN(1,COUNTA(_xlfn.ANCHORARRAY($D$2))))} -> Data Engineering | C16: GraphQL, JavaScript, API Security best practices
A17: 16 | B17: {=INDEX(_xlfn.ANCHORARRAY($D$2),RANDBETWEEN(1,COUNTA(_xlfn.ANCHORARRAY($D$2))))} -> Data Science & AI | C17: Kubernetes, security groups, Tracing
A18: 17 | B18: {=INDEX(_xlfn.ANCHORARRAY($D$2),RANDBETWEEN(1,COUNTA(_xlfn.ANCHORARRAY($D$2))))} -> BI & Reporting, Consulting | C18: Retry & exponential backoff logic, User-agent rotation, Audit logging for traceability
A19: 18 | B19: {=INDEX(_xlfn.ANCHORARRAY($D$2),RANDBETWEEN(1,COUNTA(_xlfn.ANCHORARRAY($D$2))))} -> TechOps and Automation | C19: Audit & lineage basics, Change detection, Data validation checks
... A101: 100 | B101: {=INDEX(_xlfn.ANCHORARRAY($D$2),RANDBETWEEN(1,COUNTA(_xlfn.ANCHORARRAY($D$2))))} -> Platform Engineering | C101: security groups, Network Security, SAST & DAST

Sheet Hierarchy
A1: India Hierarchy | B1: US / UK Hierarchy
A2: Software Engineer | B2: Associate Consultant
A3: Senior Software Engineer | B3: Senior Associate Consultant
A4: Solutions Enabler | B4: Consultant
A5: Solution Consultant | B5: Senior Consultant
A6: Senior Solution Consultant | B6: Manager
A7: Technical Solutions Architect | B7: Principal
A8: Principal Solutions Architect | B8: Associate Partner
B9: Partner

Sheet 6 Months Revenue
A1: Revenue:
A2: June: 4.355K
A3: May: 4.290K
A4: April: 4.177K
A5: March: 4.153K
A6: February: 4.139K
A7: January: 3.801K
